Exception on /analysis [GET]
Traceback (most recent call last):
  File "C:\Users\Jelita\Anaconda3\lib\site-packages\flask\app.py", line 2292, in wsgi_app
    response = self.full_dispatch_request()
  File "C:\Users\Jelita\Anaconda3\lib\site-packages\flask\app.py", line 1815, in full_dispatch_request
    rv = self.handle_user_exception(e)
  File "C:\Users\Jelita\Anaconda3\lib\site-packages\flask\app.py", line 1718, in handle_user_exception
    reraise(exc_type, exc_value, tb)
  File "C:\Users\Jelita\Anaconda3\lib\site-packages\flask\_compat.py", line 35, in reraise
    raise value
  File "C:\Users\Jelita\Anaconda3\lib\site-packages\flask\app.py", line 1813, in full_dispatch_request
    rv = self.dispatch_request()
  File "C:\Users\Jelita\Anaconda3\lib\site-packages\flask\app.py", line 1799, in dispatch_request
    return self.view_functions[rule.endpoint](**req.view_args)
  File "sa.py", line 72, in analysis
    post = preprocessing.postag(stopword)
  File "F:\sentimen\preprocessing.py", line 60, in postag
    ct.set_model_file('all_indo_man_tag_corpus_model.crf.tagger')
  File "C:\Users\Jelita\Anaconda3\lib\site-packages\nltk\tag\crf.py", line 96, in set_model_file
    self._tagger.open(self._model_file)
  File "pycrfsuite\_pycrfsuite.pyx", line 571, in pycrfsuite._pycrfsuite.Tagger.open
  File "pycrfsuite\_pycrfsuite.pyx", line 733, in pycrfsuite._pycrfsuite.Tagger._check_model
FileNotFoundError: [Errno 2] No such file or directory: 'all_indo_man_tag_corpus_model.crf.tagger'
Exception on /analysis [GET]
Traceback (most recent call last):
  File "C:\Users\Jelita\Anaconda3\lib\site-packages\flask\app.py", line 2292, in wsgi_app
    response = self.full_dispatch_request()
  File "C:\Users\Jelita\Anaconda3\lib\site-packages\flask\app.py", line 1815, in full_dispatch_request
    rv = self.handle_user_exception(e)
  File "C:\Users\Jelita\Anaconda3\lib\site-packages\flask\app.py", line 1718, in handle_user_exception
    reraise(exc_type, exc_value, tb)
  File "C:\Users\Jelita\Anaconda3\lib\site-packages\flask\_compat.py", line 35, in reraise
    raise value
  File "C:\Users\Jelita\Anaconda3\lib\site-packages\flask\app.py", line 1813, in full_dispatch_request
    rv = self.dispatch_request()
  File "C:\Users\Jelita\Anaconda3\lib\site-packages\flask\app.py", line 1799, in dispatch_request
    return self.view_functions[rule.endpoint](**req.view_args)
  File "sa.py", line 96, in analysis
    a += p
TypeError: must be str, not tuple
Exception on /analysis [GET]
Traceback (most recent call last):
  File "C:\Users\Jelita\Anaconda3\lib\site-packages\flask\app.py", line 2292, in wsgi_app
    response = self.full_dispatch_request()
  File "C:\Users\Jelita\Anaconda3\lib\site-packages\flask\app.py", line 1815, in full_dispatch_request
    rv = self.handle_user_exception(e)
  File "C:\Users\Jelita\Anaconda3\lib\site-packages\flask\app.py", line 1718, in handle_user_exception
    reraise(exc_type, exc_value, tb)
  File "C:\Users\Jelita\Anaconda3\lib\site-packages\flask\_compat.py", line 35, in reraise
    raise value
  File "C:\Users\Jelita\Anaconda3\lib\site-packages\flask\app.py", line 1813, in full_dispatch_request
    rv = self.dispatch_request()
  File "C:\Users\Jelita\Anaconda3\lib\site-packages\flask\app.py", line 1799, in dispatch_request
    return self.view_functions[rule.endpoint](**req.view_args)
  File "erd.py", line 96, in analysis
    a += p
TypeError: must be str, not tuple
Exception on /analysis [GET]
Traceback (most recent call last):
  File "C:\Users\Jelita\Anaconda3\lib\site-packages\flask\app.py", line 2292, in wsgi_app
    response = self.full_dispatch_request()
  File "C:\Users\Jelita\Anaconda3\lib\site-packages\flask\app.py", line 1815, in full_dispatch_request
    rv = self.handle_user_exception(e)
  File "C:\Users\Jelita\Anaconda3\lib\site-packages\flask\app.py", line 1718, in handle_user_exception
    reraise(exc_type, exc_value, tb)
  File "C:\Users\Jelita\Anaconda3\lib\site-packages\flask\_compat.py", line 35, in reraise
    raise value
  File "C:\Users\Jelita\Anaconda3\lib\site-packages\flask\app.py", line 1813, in full_dispatch_request
    rv = self.dispatch_request()
  File "C:\Users\Jelita\Anaconda3\lib\site-packages\flask\app.py", line 1799, in dispatch_request
    return self.view_functions[rule.endpoint](**req.view_args)
  File "erd.py", line 96, in analysis
    a += p
TypeError: must be str, not tuple
Exception on /analysis [GET]
Traceback (most recent call last):
  File "C:\Users\Jelita\Anaconda3\lib\site-packages\flask\app.py", line 2292, in wsgi_app
    response = self.full_dispatch_request()
  File "C:\Users\Jelita\Anaconda3\lib\site-packages\flask\app.py", line 1815, in full_dispatch_request
    rv = self.handle_user_exception(e)
  File "C:\Users\Jelita\Anaconda3\lib\site-packages\flask\app.py", line 1718, in handle_user_exception
    reraise(exc_type, exc_value, tb)
  File "C:\Users\Jelita\Anaconda3\lib\site-packages\flask\_compat.py", line 35, in reraise
    raise value
  File "C:\Users\Jelita\Anaconda3\lib\site-packages\flask\app.py", line 1813, in full_dispatch_request
    rv = self.dispatch_request()
  File "C:\Users\Jelita\Anaconda3\lib\site-packages\flask\app.py", line 1799, in dispatch_request
    return self.view_functions[rule.endpoint](**req.view_args)
  File "erd.py", line 84, in analysis
    for katas in posst:
NameError: name 'posst' is not defined
Exception on /analysis [GET]
Traceback (most recent call last):
  File "C:\Users\Jelita\Anaconda3\lib\site-packages\flask\app.py", line 2292, in wsgi_app
    response = self.full_dispatch_request()
  File "C:\Users\Jelita\Anaconda3\lib\site-packages\flask\app.py", line 1815, in full_dispatch_request
    rv = self.handle_user_exception(e)
  File "C:\Users\Jelita\Anaconda3\lib\site-packages\flask\app.py", line 1718, in handle_user_exception
    reraise(exc_type, exc_value, tb)
  File "C:\Users\Jelita\Anaconda3\lib\site-packages\flask\_compat.py", line 35, in reraise
    raise value
  File "C:\Users\Jelita\Anaconda3\lib\site-packages\flask\app.py", line 1813, in full_dispatch_request
    rv = self.dispatch_request()
  File "C:\Users\Jelita\Anaconda3\lib\site-packages\flask\app.py", line 1799, in dispatch_request
    return self.view_functions[rule.endpoint](**req.view_args)
  File "erd.py", line 84, in analysis
    for katas in posst:
NameError: name 'posst' is not defined
Exception on /analysis [GET]
Traceback (most recent call last):
  File "C:\Users\Pittri\Anaconda3\lib\site-packages\flask\app.py", line 2292, in wsgi_app
    response = self.full_dispatch_request()
  File "C:\Users\Pittri\Anaconda3\lib\site-packages\flask\app.py", line 1815, in full_dispatch_request
    rv = self.handle_user_exception(e)
  File "C:\Users\Pittri\Anaconda3\lib\site-packages\flask\app.py", line 1718, in handle_user_exception
    reraise(exc_type, exc_value, tb)
  File "C:\Users\Pittri\Anaconda3\lib\site-packages\flask\_compat.py", line 35, in reraise
    raise value
  File "C:\Users\Pittri\Anaconda3\lib\site-packages\flask\app.py", line 1813, in full_dispatch_request
    rv = self.dispatch_request()
  File "C:\Users\Pittri\Anaconda3\lib\site-packages\flask\app.py", line 1799, in dispatch_request
    return self.view_functions[rule.endpoint](**req.view_args)
  File "sa.py", line 80, in analysis
    return render_template('submit.html', jason=jsonify(jason))
  File "C:\Users\Pittri\Anaconda3\lib\site-packages\flask\templating.py", line 135, in render_template
    context, ctx.app)
  File "C:\Users\Pittri\Anaconda3\lib\site-packages\flask\templating.py", line 117, in _render
    rv = template.render(context)
  File "C:\Users\Pittri\Anaconda3\lib\site-packages\jinja2\asyncsupport.py", line 76, in render
    return original_render(self, *args, **kwargs)
  File "C:\Users\Pittri\Anaconda3\lib\site-packages\jinja2\environment.py", line 1008, in render
    return self.environment.handle_exception(exc_info, True)
  File "C:\Users\Pittri\Anaconda3\lib\site-packages\jinja2\environment.py", line 780, in handle_exception
    reraise(exc_type, exc_value, tb)
  File "C:\Users\Pittri\Anaconda3\lib\site-packages\jinja2\_compat.py", line 37, in reraise
    raise value.with_traceback(tb)
  File "C:\Users\Pittri\Documents\TA-02\After Pra Sidang\erd\templates\submit.html", line 1, in top-level template code
    {% extends "base.html" %}
  File "C:\Users\Pittri\Documents\TA-02\After Pra Sidang\erd\templates\base.html", line 31, in top-level template code
    {% block content %}
  File "C:\Users\Pittri\Documents\TA-02\After Pra Sidang\erd\templates\submit.html", line 8, in block "content"
    {{ form.hidden_tag() }}
  File "C:\Users\Pittri\Anaconda3\lib\site-packages\jinja2\environment.py", line 430, in getattr
    return getattr(obj, attribute)
jinja2.exceptions.UndefinedError: 'form' is undefined
Exception on /analysis [GET]
Traceback (most recent call last):
  File "C:\Users\Pittri\Anaconda3\lib\site-packages\flask\app.py", line 2292, in wsgi_app
    response = self.full_dispatch_request()
  File "C:\Users\Pittri\Anaconda3\lib\site-packages\flask\app.py", line 1815, in full_dispatch_request
    rv = self.handle_user_exception(e)
  File "C:\Users\Pittri\Anaconda3\lib\site-packages\flask\app.py", line 1718, in handle_user_exception
    reraise(exc_type, exc_value, tb)
  File "C:\Users\Pittri\Anaconda3\lib\site-packages\flask\_compat.py", line 35, in reraise
    raise value
  File "C:\Users\Pittri\Anaconda3\lib\site-packages\flask\app.py", line 1813, in full_dispatch_request
    rv = self.dispatch_request()
  File "C:\Users\Pittri\Anaconda3\lib\site-packages\flask\app.py", line 1799, in dispatch_request
    return self.view_functions[rule.endpoint](**req.view_args)
  File "sa.py", line 80, in analysis
    return render_template('home.html', jason=jsonify(jason))
  File "C:\Users\Pittri\Anaconda3\lib\site-packages\flask\templating.py", line 135, in render_template
    context, ctx.app)
  File "C:\Users\Pittri\Anaconda3\lib\site-packages\flask\templating.py", line 117, in _render
    rv = template.render(context)
  File "C:\Users\Pittri\Anaconda3\lib\site-packages\jinja2\asyncsupport.py", line 76, in render
    return original_render(self, *args, **kwargs)
  File "C:\Users\Pittri\Anaconda3\lib\site-packages\jinja2\environment.py", line 1008, in render
    return self.environment.handle_exception(exc_info, True)
  File "C:\Users\Pittri\Anaconda3\lib\site-packages\jinja2\environment.py", line 780, in handle_exception
    reraise(exc_type, exc_value, tb)
  File "C:\Users\Pittri\Anaconda3\lib\site-packages\jinja2\_compat.py", line 37, in reraise
    raise value.with_traceback(tb)
  File "C:\Users\Pittri\Documents\TA-02\After Pra Sidang\erd\templates\home.html", line 1, in top-level template code
    {% extends "base.html" %}
  File "C:\Users\Pittri\Documents\TA-02\After Pra Sidang\erd\templates\base.html", line 31, in top-level template code
    {% block content %}
  File "C:\Users\Pittri\Documents\TA-02\After Pra Sidang\erd\templates\home.html", line 8, in block "content"
    {{ form.hidden_tag() }}
  File "C:\Users\Pittri\Anaconda3\lib\site-packages\jinja2\environment.py", line 430, in getattr
    return getattr(obj, attribute)
jinja2.exceptions.UndefinedError: 'form' is undefined
Exception on /analysis [GET]
Traceback (most recent call last):
  File "C:\Users\Pittri\Anaconda3\lib\site-packages\flask\app.py", line 2292, in wsgi_app
    response = self.full_dispatch_request()
  File "C:\Users\Pittri\Anaconda3\lib\site-packages\flask\app.py", line 1815, in full_dispatch_request
    rv = self.handle_user_exception(e)
  File "C:\Users\Pittri\Anaconda3\lib\site-packages\flask\app.py", line 1718, in handle_user_exception
    reraise(exc_type, exc_value, tb)
  File "C:\Users\Pittri\Anaconda3\lib\site-packages\flask\_compat.py", line 35, in reraise
    raise value
  File "C:\Users\Pittri\Anaconda3\lib\site-packages\flask\app.py", line 1813, in full_dispatch_request
    rv = self.dispatch_request()
  File "C:\Users\Pittri\Anaconda3\lib\site-packages\flask\app.py", line 1799, in dispatch_request
    return self.view_functions[rule.endpoint](**req.view_args)
  File "sa.py", line 80, in analysis
    return render_template('home.html', jason=jsonify(jason))
  File "C:\Users\Pittri\Anaconda3\lib\site-packages\flask\templating.py", line 135, in render_template
    context, ctx.app)
  File "C:\Users\Pittri\Anaconda3\lib\site-packages\flask\templating.py", line 117, in _render
    rv = template.render(context)
  File "C:\Users\Pittri\Anaconda3\lib\site-packages\jinja2\asyncsupport.py", line 76, in render
    return original_render(self, *args, **kwargs)
  File "C:\Users\Pittri\Anaconda3\lib\site-packages\jinja2\environment.py", line 1008, in render
    return self.environment.handle_exception(exc_info, True)
  File "C:\Users\Pittri\Anaconda3\lib\site-packages\jinja2\environment.py", line 780, in handle_exception
    reraise(exc_type, exc_value, tb)
  File "C:\Users\Pittri\Anaconda3\lib\site-packages\jinja2\_compat.py", line 37, in reraise
    raise value.with_traceback(tb)
  File "C:\Users\Pittri\Documents\TA-02\After Pra Sidang\erd\templates\home.html", line 1, in top-level template code
    {% extends "base.html" %}
  File "C:\Users\Pittri\Documents\TA-02\After Pra Sidang\erd\templates\base.html", line 31, in top-level template code
    {% block content %}
  File "C:\Users\Pittri\Documents\TA-02\After Pra Sidang\erd\templates\home.html", line 8, in block "content"
    {{ form.hidden_tag() }}
  File "C:\Users\Pittri\Anaconda3\lib\site-packages\jinja2\environment.py", line 430, in getattr
    return getattr(obj, attribute)
jinja2.exceptions.UndefinedError: 'form' is undefined
Exception on /analysis [GET]
Traceback (most recent call last):
  File "C:\Users\Pittri\Anaconda3\lib\site-packages\flask\app.py", line 2292, in wsgi_app
    response = self.full_dispatch_request()
  File "C:\Users\Pittri\Anaconda3\lib\site-packages\flask\app.py", line 1815, in full_dispatch_request
    rv = self.handle_user_exception(e)
  File "C:\Users\Pittri\Anaconda3\lib\site-packages\flask\app.py", line 1718, in handle_user_exception
    reraise(exc_type, exc_value, tb)
  File "C:\Users\Pittri\Anaconda3\lib\site-packages\flask\_compat.py", line 35, in reraise
    raise value
  File "C:\Users\Pittri\Anaconda3\lib\site-packages\flask\app.py", line 1813, in full_dispatch_request
    rv = self.dispatch_request()
  File "C:\Users\Pittri\Anaconda3\lib\site-packages\flask\app.py", line 1799, in dispatch_request
    return self.view_functions[rule.endpoint](**req.view_args)
  File "sa.py", line 80, in analysis
    #     return render_template('analysis.html', pos_sent=pos_sent, neg_sent=neg_sent, word_cloud=word_cloud)
  File "C:\Users\Pittri\Anaconda3\lib\site-packages\flask\templating.py", line 135, in render_template
    context, ctx.app)
  File "C:\Users\Pittri\Anaconda3\lib\site-packages\flask\templating.py", line 117, in _render
    rv = template.render(context)
  File "C:\Users\Pittri\Anaconda3\lib\site-packages\jinja2\asyncsupport.py", line 76, in render
    return original_render(self, *args, **kwargs)
  File "C:\Users\Pittri\Anaconda3\lib\site-packages\jinja2\environment.py", line 1008, in render
    return self.environment.handle_exception(exc_info, True)
  File "C:\Users\Pittri\Anaconda3\lib\site-packages\jinja2\environment.py", line 780, in handle_exception
    reraise(exc_type, exc_value, tb)
  File "C:\Users\Pittri\Anaconda3\lib\site-packages\jinja2\_compat.py", line 37, in reraise
    raise value.with_traceback(tb)
  File "C:\Users\Pittri\Downloads\QE\inre\inre\templates\home.html", line 1, in top-level template code
    {% extends "base.html" %}
  File "C:\Users\Pittri\Downloads\QE\inre\inre\templates\base.html", line 31, in top-level template code
    {% block content %}
  File "C:\Users\Pittri\Downloads\QE\inre\inre\templates\home.html", line 8, in block "content"
    {{ form.hidden_tag() }}
  File "C:\Users\Pittri\Anaconda3\lib\site-packages\jinja2\environment.py", line 430, in getattr
    return getattr(obj, attribute)
jinja2.exceptions.UndefinedError: 'form' is undefined
Exception on /analysis [GET]
Traceback (most recent call last):
  File "C:\Users\Pittri\Anaconda3\lib\site-packages\flask\app.py", line 2292, in wsgi_app
    response = self.full_dispatch_request()
  File "C:\Users\Pittri\Anaconda3\lib\site-packages\flask\app.py", line 1815, in full_dispatch_request
    rv = self.handle_user_exception(e)
  File "C:\Users\Pittri\Anaconda3\lib\site-packages\flask\app.py", line 1718, in handle_user_exception
    reraise(exc_type, exc_value, tb)
  File "C:\Users\Pittri\Anaconda3\lib\site-packages\flask\_compat.py", line 35, in reraise
    raise value
  File "C:\Users\Pittri\Anaconda3\lib\site-packages\flask\app.py", line 1813, in full_dispatch_request
    rv = self.dispatch_request()
  File "C:\Users\Pittri\Anaconda3\lib\site-packages\flask\app.py", line 1799, in dispatch_request
    return self.view_functions[rule.endpoint](**req.view_args)
  File "sa.py", line 85, in analysis
    filename = allFile(location)
NameError: name 'allFile' is not defined
Exception on /analysis [GET]
Traceback (most recent call last):
  File "C:\Users\Pittri\Anaconda3\lib\site-packages\flask\app.py", line 2292, in wsgi_app
    response = self.full_dispatch_request()
  File "C:\Users\Pittri\Anaconda3\lib\site-packages\flask\app.py", line 1815, in full_dispatch_request
    rv = self.handle_user_exception(e)
  File "C:\Users\Pittri\Anaconda3\lib\site-packages\flask\app.py", line 1718, in handle_user_exception
    reraise(exc_type, exc_value, tb)
  File "C:\Users\Pittri\Anaconda3\lib\site-packages\flask\_compat.py", line 35, in reraise
    raise value
  File "C:\Users\Pittri\Anaconda3\lib\site-packages\flask\app.py", line 1813, in full_dispatch_request
    rv = self.dispatch_request()
  File "C:\Users\Pittri\Anaconda3\lib\site-packages\flask\app.py", line 1799, in dispatch_request
    return self.view_functions[rule.endpoint](**req.view_args)
  File "sa.py", line 86, in analysis
    filename = allFile(location)
NameError: name 'allFile' is not defined
Exception on /analysis [GET]
Traceback (most recent call last):
  File "C:\Users\Pittri\Anaconda3\lib\site-packages\flask\app.py", line 2292, in wsgi_app
    response = self.full_dispatch_request()
  File "C:\Users\Pittri\Anaconda3\lib\site-packages\flask\app.py", line 1815, in full_dispatch_request
    rv = self.handle_user_exception(e)
  File "C:\Users\Pittri\Anaconda3\lib\site-packages\flask\app.py", line 1718, in handle_user_exception
    reraise(exc_type, exc_value, tb)
  File "C:\Users\Pittri\Anaconda3\lib\site-packages\flask\_compat.py", line 35, in reraise
    raise value
  File "C:\Users\Pittri\Anaconda3\lib\site-packages\flask\app.py", line 1813, in full_dispatch_request
    rv = self.dispatch_request()
  File "C:\Users\Pittri\Anaconda3\lib\site-packages\flask\app.py", line 1799, in dispatch_request
    return self.view_functions[rule.endpoint](**req.view_args)
  File "sa.py", line 109, in analysis
    exportIndex(index, 'INDE.txt')
NameError: name 'exportIndex' is not defined
Exception on /analysis [GET]
Traceback (most recent call last):
  File "C:\Users\Pittri\Anaconda3\lib\site-packages\flask\app.py", line 2292, in wsgi_app
    response = self.full_dispatch_request()
  File "C:\Users\Pittri\Anaconda3\lib\site-packages\flask\app.py", line 1816, in full_dispatch_request
    return self.finalize_request(rv)
  File "C:\Users\Pittri\Anaconda3\lib\site-packages\flask\app.py", line 1831, in finalize_request
    response = self.make_response(rv)
  File "C:\Users\Pittri\Anaconda3\lib\site-packages\flask\app.py", line 1957, in make_response
    'The view function did not return a valid response. The'
TypeError: The view function did not return a valid response. The function either returned None or ended without a return statement.
Exception on /analysis [GET]
Traceback (most recent call last):
  File "C:\Users\Pittri\Anaconda3\lib\site-packages\flask\app.py", line 2292, in wsgi_app
    response = self.full_dispatch_request()
  File "C:\Users\Pittri\Anaconda3\lib\site-packages\flask\app.py", line 1815, in full_dispatch_request
    rv = self.handle_user_exception(e)
  File "C:\Users\Pittri\Anaconda3\lib\site-packages\flask\app.py", line 1718, in handle_user_exception
    reraise(exc_type, exc_value, tb)
  File "C:\Users\Pittri\Anaconda3\lib\site-packages\flask\_compat.py", line 35, in reraise
    raise value
  File "C:\Users\Pittri\Anaconda3\lib\site-packages\flask\app.py", line 1813, in full_dispatch_request
    rv = self.dispatch_request()
  File "C:\Users\Pittri\Anaconda3\lib\site-packages\flask\app.py", line 1799, in dispatch_request
    return self.view_functions[rule.endpoint](**req.view_args)
  File "sa.py", line 110, in analysis
    return render_template('submit.html')
  File "C:\Users\Pittri\Anaconda3\lib\site-packages\flask\templating.py", line 135, in render_template
    context, ctx.app)
  File "C:\Users\Pittri\Anaconda3\lib\site-packages\flask\templating.py", line 117, in _render
    rv = template.render(context)
  File "C:\Users\Pittri\Anaconda3\lib\site-packages\jinja2\asyncsupport.py", line 76, in render
    return original_render(self, *args, **kwargs)
  File "C:\Users\Pittri\Anaconda3\lib\site-packages\jinja2\environment.py", line 1008, in render
    return self.environment.handle_exception(exc_info, True)
  File "C:\Users\Pittri\Anaconda3\lib\site-packages\jinja2\environment.py", line 780, in handle_exception
    reraise(exc_type, exc_value, tb)
  File "C:\Users\Pittri\Anaconda3\lib\site-packages\jinja2\_compat.py", line 37, in reraise
    raise value.with_traceback(tb)
  File "C:\Users\Pittri\Downloads\QE\inre\inre\templates\submit.html", line 1, in top-level template code
    {% extends "base.html" %}
  File "C:\Users\Pittri\Downloads\QE\inre\inre\templates\base.html", line 31, in top-level template code
    {% block content %}
  File "C:\Users\Pittri\Downloads\QE\inre\inre\templates\submit.html", line 9, in block "content"
    {{ form.hidden_tag() }}
  File "C:\Users\Pittri\Anaconda3\lib\site-packages\jinja2\environment.py", line 430, in getattr
    return getattr(obj, attribute)
jinja2.exceptions.UndefinedError: 'form' is undefined
Exception on /analysis [GET]
Traceback (most recent call last):
  File "C:\Users\Pittri\Anaconda3\lib\site-packages\flask\app.py", line 2292, in wsgi_app
    response = self.full_dispatch_request()
  File "C:\Users\Pittri\Anaconda3\lib\site-packages\flask\app.py", line 1815, in full_dispatch_request
    rv = self.handle_user_exception(e)
  File "C:\Users\Pittri\Anaconda3\lib\site-packages\flask\app.py", line 1718, in handle_user_exception
    reraise(exc_type, exc_value, tb)
  File "C:\Users\Pittri\Anaconda3\lib\site-packages\flask\_compat.py", line 35, in reraise
    raise value
  File "C:\Users\Pittri\Anaconda3\lib\site-packages\flask\app.py", line 1813, in full_dispatch_request
    rv = self.dispatch_request()
  File "C:\Users\Pittri\Anaconda3\lib\site-packages\flask\app.py", line 1799, in dispatch_request
    return self.view_functions[rule.endpoint](**req.view_args)
  File "sa.py", line 110, in analysis
    query = preprocessing.removePunctuation(raw_query)
NameError: name 'raw_query' is not defined
Exception on /analysis [GET]
Traceback (most recent call last):
  File "C:\Users\Pittri\Anaconda3\lib\site-packages\flask\app.py", line 2292, in wsgi_app
    response = self.full_dispatch_request()
  File "C:\Users\Pittri\Anaconda3\lib\site-packages\flask\app.py", line 1815, in full_dispatch_request
    rv = self.handle_user_exception(e)
  File "C:\Users\Pittri\Anaconda3\lib\site-packages\flask\app.py", line 1718, in handle_user_exception
    reraise(exc_type, exc_value, tb)
  File "C:\Users\Pittri\Anaconda3\lib\site-packages\flask\_compat.py", line 35, in reraise
    raise value
  File "C:\Users\Pittri\Anaconda3\lib\site-packages\flask\app.py", line 1813, in full_dispatch_request
    rv = self.dispatch_request()
  File "C:\Users\Pittri\Anaconda3\lib\site-packages\flask\app.py", line 1799, in dispatch_request
    return self.view_functions[rule.endpoint](**req.view_args)
  File "sa.py", line 112, in analysis
    query = preprocessing.removePunctuation(raw_query)
NameError: name 'raw_query' is not defined
Exception on /analysis [GET]
Traceback (most recent call last):
  File "C:\Users\Pittri\Anaconda3\lib\site-packages\flask\app.py", line 2292, in wsgi_app
    response = self.full_dispatch_request()
  File "C:\Users\Pittri\Anaconda3\lib\site-packages\flask\app.py", line 1815, in full_dispatch_request
    rv = self.handle_user_exception(e)
  File "C:\Users\Pittri\Anaconda3\lib\site-packages\flask\app.py", line 1718, in handle_user_exception
    reraise(exc_type, exc_value, tb)
  File "C:\Users\Pittri\Anaconda3\lib\site-packages\flask\_compat.py", line 35, in reraise
    raise value
  File "C:\Users\Pittri\Anaconda3\lib\site-packages\flask\app.py", line 1813, in full_dispatch_request
    rv = self.dispatch_request()
  File "C:\Users\Pittri\Anaconda3\lib\site-packages\flask\app.py", line 1799, in dispatch_request
    return self.view_functions[rule.endpoint](**req.view_args)
  File "sa.py", line 112, in analysis
    query = preprocessing.removePunctuation(query_search)
  File "C:\Users\Pittri\Downloads\QE\inre\inre\preprocessing.py", line 52, in removePunctuation
    textList[i] = textList[i].replace(punct, " ")
TypeError: 'str' object does not support item assignment
Exception on /analysis [GET]
Traceback (most recent call last):
  File "C:\Users\Pittri\Anaconda3\lib\site-packages\flask\app.py", line 2292, in wsgi_app
    response = self.full_dispatch_request()
  File "C:\Users\Pittri\Anaconda3\lib\site-packages\flask\app.py", line 1815, in full_dispatch_request
    rv = self.handle_user_exception(e)
  File "C:\Users\Pittri\Anaconda3\lib\site-packages\flask\app.py", line 1718, in handle_user_exception
    reraise(exc_type, exc_value, tb)
  File "C:\Users\Pittri\Anaconda3\lib\site-packages\flask\_compat.py", line 35, in reraise
    raise value
  File "C:\Users\Pittri\Anaconda3\lib\site-packages\flask\app.py", line 1813, in full_dispatch_request
    rv = self.dispatch_request()
  File "C:\Users\Pittri\Anaconda3\lib\site-packages\flask\app.py", line 1799, in dispatch_request
    return self.view_functions[rule.endpoint](**req.view_args)
  File "sa.py", line 95, in analysis
    text = preprocessing.removePunctuation(extracted)
  File "C:\Users\Pittri\Downloads\QE\inre\inre\preprocessing.py", line 53, in removePunctuation
    textList = textList.replace(punct, " ")
AttributeError: 'list' object has no attribute 'replace'
Exception on /analysis [GET]
Traceback (most recent call last):
  File "C:\Users\Pittri\Anaconda3\lib\site-packages\flask\app.py", line 2292, in wsgi_app
    response = self.full_dispatch_request()
  File "C:\Users\Pittri\Anaconda3\lib\site-packages\flask\app.py", line 1815, in full_dispatch_request
    rv = self.handle_user_exception(e)
  File "C:\Users\Pittri\Anaconda3\lib\site-packages\flask\app.py", line 1718, in handle_user_exception
    reraise(exc_type, exc_value, tb)
  File "C:\Users\Pittri\Anaconda3\lib\site-packages\flask\_compat.py", line 35, in reraise
    raise value
  File "C:\Users\Pittri\Anaconda3\lib\site-packages\flask\app.py", line 1813, in full_dispatch_request
    rv = self.dispatch_request()
  File "C:\Users\Pittri\Anaconda3\lib\site-packages\flask\app.py", line 1799, in dispatch_request
    return self.view_functions[rule.endpoint](**req.view_args)
  File "sa.py", line 112, in analysis
    query = preprocessing.removePunctuation(query_search)
  File "C:\Users\Pittri\Downloads\QE\inre\inre\preprocessing.py", line 52, in removePunctuation
    textList[i] = textList[i].replace(punct, " ")
TypeError: 'str' object does not support item assignment
Exception on /analysis [GET]
Traceback (most recent call last):
  File "C:\Users\Pittri\Anaconda3\lib\site-packages\flask\app.py", line 2292, in wsgi_app
    response = self.full_dispatch_request()
  File "C:\Users\Pittri\Anaconda3\lib\site-packages\flask\app.py", line 1815, in full_dispatch_request
    rv = self.handle_user_exception(e)
  File "C:\Users\Pittri\Anaconda3\lib\site-packages\flask\app.py", line 1718, in handle_user_exception
    reraise(exc_type, exc_value, tb)
  File "C:\Users\Pittri\Anaconda3\lib\site-packages\flask\_compat.py", line 35, in reraise
    raise value
  File "C:\Users\Pittri\Anaconda3\lib\site-packages\flask\app.py", line 1813, in full_dispatch_request
    rv = self.dispatch_request()
  File "C:\Users\Pittri\Anaconda3\lib\site-packages\flask\app.py", line 1799, in dispatch_request
    return self.view_functions[rule.endpoint](**req.view_args)
  File "sa.py", line 112, in analysis
    query = preprocessing.removePunctuation(query_search)
  File "E:\inre01\inre\preprocessing.py", line 52, in removePunctuation
    textList[i] = textList[i].replace(punct, " ")
TypeError: 'str' object does not support item assignment
Exception on /analysis [GET]
Traceback (most recent call last):
  File "C:\Users\Pittri\Anaconda3\lib\site-packages\flask\app.py", line 2292, in wsgi_app
    response = self.full_dispatch_request()
  File "C:\Users\Pittri\Anaconda3\lib\site-packages\flask\app.py", line 1815, in full_dispatch_request
    rv = self.handle_user_exception(e)
  File "C:\Users\Pittri\Anaconda3\lib\site-packages\flask\app.py", line 1718, in handle_user_exception
    reraise(exc_type, exc_value, tb)
  File "C:\Users\Pittri\Anaconda3\lib\site-packages\flask\_compat.py", line 35, in reraise
    raise value
  File "C:\Users\Pittri\Anaconda3\lib\site-packages\flask\app.py", line 1813, in full_dispatch_request
    rv = self.dispatch_request()
  File "C:\Users\Pittri\Anaconda3\lib\site-packages\flask\app.py", line 1799, in dispatch_request
    return self.view_functions[rule.endpoint](**req.view_args)
  File "sa.py", line 112, in analysis
    query = preprocessing.removePunctuation(query_search)
  File "E:\inre01\inre\preprocessing.py", line 52, in removePunctuation
    textList[i] = textList[i].replace(punct, " ")
TypeError: 'str' object does not support item assignment
Exception on /analysis [GET]
Traceback (most recent call last):
  File "C:\Users\Pittri\Anaconda3\lib\site-packages\flask\app.py", line 2292, in wsgi_app
    response = self.full_dispatch_request()
  File "C:\Users\Pittri\Anaconda3\lib\site-packages\flask\app.py", line 1815, in full_dispatch_request
    rv = self.handle_user_exception(e)
  File "C:\Users\Pittri\Anaconda3\lib\site-packages\flask\app.py", line 1718, in handle_user_exception
    reraise(exc_type, exc_value, tb)
  File "C:\Users\Pittri\Anaconda3\lib\site-packages\flask\_compat.py", line 35, in reraise
    raise value
  File "C:\Users\Pittri\Anaconda3\lib\site-packages\flask\app.py", line 1813, in full_dispatch_request
    rv = self.dispatch_request()
  File "C:\Users\Pittri\Anaconda3\lib\site-packages\flask\app.py", line 1799, in dispatch_request
    return self.view_functions[rule.endpoint](**req.view_args)
  File "sa.py", line 112, in analysis
    query = preprocessing.removePunctuation(query_search)
  File "E:\inre01\inre\preprocessing.py", line 53, in removePunctuation
    textList[i] = textList[i].replace(punct, " ")
TypeError: 'str' object does not support item assignment
Exception on /analysis [GET]
Traceback (most recent call last):
  File "C:\Users\Pittri\Anaconda3\lib\site-packages\flask\app.py", line 1974, in make_response
    rv = self.response_class.force_type(rv, request.environ)
  File "C:\Users\Pittri\Anaconda3\lib\site-packages\werkzeug\wrappers.py", line 921, in force_type
    response = BaseResponse(*_run_wsgi_app(response, environ))
  File "C:\Users\Pittri\Anaconda3\lib\site-packages\werkzeug\wrappers.py", line 59, in _run_wsgi_app
    return _run_wsgi_app(*args)
  File "C:\Users\Pittri\Anaconda3\lib\site-packages\werkzeug\test.py", line 923, in run_wsgi_app
    app_rv = app(environ, start_response)
TypeError: 'int' object is not callable

During handling of the above exception, another exception occurred:

Traceback (most recent call last):
  File "C:\Users\Pittri\Anaconda3\lib\site-packages\flask\app.py", line 2292, in wsgi_app
    response = self.full_dispatch_request()
  File "C:\Users\Pittri\Anaconda3\lib\site-packages\flask\app.py", line 1816, in full_dispatch_request
    return self.finalize_request(rv)
  File "C:\Users\Pittri\Anaconda3\lib\site-packages\flask\app.py", line 1831, in finalize_request
    response = self.make_response(rv)
  File "C:\Users\Pittri\Anaconda3\lib\site-packages\flask\app.py", line 1982, in make_response
    reraise(TypeError, new_error, sys.exc_info()[2])
  File "C:\Users\Pittri\Anaconda3\lib\site-packages\flask\_compat.py", line 34, in reraise
    raise value.with_traceback(tb)
  File "C:\Users\Pittri\Anaconda3\lib\site-packages\flask\app.py", line 1974, in make_response
    rv = self.response_class.force_type(rv, request.environ)
  File "C:\Users\Pittri\Anaconda3\lib\site-packages\werkzeug\wrappers.py", line 921, in force_type
    response = BaseResponse(*_run_wsgi_app(response, environ))
  File "C:\Users\Pittri\Anaconda3\lib\site-packages\werkzeug\wrappers.py", line 59, in _run_wsgi_app
    return _run_wsgi_app(*args)
  File "C:\Users\Pittri\Anaconda3\lib\site-packages\werkzeug\test.py", line 923, in run_wsgi_app
    app_rv = app(environ, start_response)
TypeError: 'int' object is not callable
The view function did not return a valid response. The return type must be a string, tuple, Response instance, or WSGI callable, but it was a int.
Exception on /analysis [GET]
Traceback (most recent call last):
  File "C:\Users\Pittri\Anaconda3\lib\site-packages\flask\app.py", line 1974, in make_response
    rv = self.response_class.force_type(rv, request.environ)
  File "C:\Users\Pittri\Anaconda3\lib\site-packages\werkzeug\wrappers.py", line 921, in force_type
    response = BaseResponse(*_run_wsgi_app(response, environ))
  File "C:\Users\Pittri\Anaconda3\lib\site-packages\werkzeug\wrappers.py", line 59, in _run_wsgi_app
    return _run_wsgi_app(*args)
  File "C:\Users\Pittri\Anaconda3\lib\site-packages\werkzeug\test.py", line 923, in run_wsgi_app
    app_rv = app(environ, start_response)
TypeError: 'list' object is not callable

During handling of the above exception, another exception occurred:

Traceback (most recent call last):
  File "C:\Users\Pittri\Anaconda3\lib\site-packages\flask\app.py", line 2292, in wsgi_app
    response = self.full_dispatch_request()
  File "C:\Users\Pittri\Anaconda3\lib\site-packages\flask\app.py", line 1816, in full_dispatch_request
    return self.finalize_request(rv)
  File "C:\Users\Pittri\Anaconda3\lib\site-packages\flask\app.py", line 1831, in finalize_request
    response = self.make_response(rv)
  File "C:\Users\Pittri\Anaconda3\lib\site-packages\flask\app.py", line 1982, in make_response
    reraise(TypeError, new_error, sys.exc_info()[2])
  File "C:\Users\Pittri\Anaconda3\lib\site-packages\flask\_compat.py", line 34, in reraise
    raise value.with_traceback(tb)
  File "C:\Users\Pittri\Anaconda3\lib\site-packages\flask\app.py", line 1974, in make_response
    rv = self.response_class.force_type(rv, request.environ)
  File "C:\Users\Pittri\Anaconda3\lib\site-packages\werkzeug\wrappers.py", line 921, in force_type
    response = BaseResponse(*_run_wsgi_app(response, environ))
  File "C:\Users\Pittri\Anaconda3\lib\site-packages\werkzeug\wrappers.py", line 59, in _run_wsgi_app
    return _run_wsgi_app(*args)
  File "C:\Users\Pittri\Anaconda3\lib\site-packages\werkzeug\test.py", line 923, in run_wsgi_app
    app_rv = app(environ, start_response)
TypeError: 'list' object is not callable
The view function did not return a valid response. The return type must be a string, tuple, Response instance, or WSGI callable, but it was a list.
Exception on /analysis [GET]
Traceback (most recent call last):
  File "C:\Users\Pittri\Anaconda3\lib\site-packages\flask\app.py", line 2292, in wsgi_app
    response = self.full_dispatch_request()
  File "C:\Users\Pittri\Anaconda3\lib\site-packages\flask\app.py", line 1815, in full_dispatch_request
    rv = self.handle_user_exception(e)
  File "C:\Users\Pittri\Anaconda3\lib\site-packages\flask\app.py", line 1718, in handle_user_exception
    reraise(exc_type, exc_value, tb)
  File "C:\Users\Pittri\Anaconda3\lib\site-packages\flask\_compat.py", line 35, in reraise
    raise value
  File "C:\Users\Pittri\Anaconda3\lib\site-packages\flask\app.py", line 1813, in full_dispatch_request
    rv = self.dispatch_request()
  File "C:\Users\Pittri\Anaconda3\lib\site-packages\flask\app.py", line 1799, in dispatch_request
    return self.view_functions[rule.endpoint](**req.view_args)
  File "sa.py", line 95, in analysis
    text = preprocessing.removePunctuation(extracted)
  File "E:\inre01\inre\preprocessing.py", line 55, in removePunctuation
    textList = li.replace(punct, " ")
AttributeError: 'list' object has no attribute 'replace'
Exception on /analysis [GET]
Traceback (most recent call last):
  File "C:\Users\Pittri\Anaconda3\lib\site-packages\flask\app.py", line 2292, in wsgi_app
    response = self.full_dispatch_request()
  File "C:\Users\Pittri\Anaconda3\lib\site-packages\flask\app.py", line 1815, in full_dispatch_request
    rv = self.handle_user_exception(e)
  File "C:\Users\Pittri\Anaconda3\lib\site-packages\flask\app.py", line 1718, in handle_user_exception
    reraise(exc_type, exc_value, tb)
  File "C:\Users\Pittri\Anaconda3\lib\site-packages\flask\_compat.py", line 35, in reraise
    raise value
  File "C:\Users\Pittri\Anaconda3\lib\site-packages\flask\app.py", line 1813, in full_dispatch_request
    rv = self.dispatch_request()
  File "C:\Users\Pittri\Anaconda3\lib\site-packages\flask\app.py", line 1799, in dispatch_request
    return self.view_functions[rule.endpoint](**req.view_args)
  File "sa.py", line 96, in analysis
    text = preprocessing.caseFolding(text)
UnboundLocalError: local variable 'text' referenced before assignment
Exception on /analysis [GET]
Traceback (most recent call last):
  File "C:\Users\Pittri\Anaconda3\lib\site-packages\flask\app.py", line 1974, in make_response
    rv = self.response_class.force_type(rv, request.environ)
  File "C:\Users\Pittri\Anaconda3\lib\site-packages\werkzeug\wrappers.py", line 921, in force_type
    response = BaseResponse(*_run_wsgi_app(response, environ))
  File "C:\Users\Pittri\Anaconda3\lib\site-packages\werkzeug\wrappers.py", line 59, in _run_wsgi_app
    return _run_wsgi_app(*args)
  File "C:\Users\Pittri\Anaconda3\lib\site-packages\werkzeug\test.py", line 923, in run_wsgi_app
    app_rv = app(environ, start_response)
TypeError: 'list' object is not callable

During handling of the above exception, another exception occurred:

Traceback (most recent call last):
  File "C:\Users\Pittri\Anaconda3\lib\site-packages\flask\app.py", line 2292, in wsgi_app
    response = self.full_dispatch_request()
  File "C:\Users\Pittri\Anaconda3\lib\site-packages\flask\app.py", line 1816, in full_dispatch_request
    return self.finalize_request(rv)
  File "C:\Users\Pittri\Anaconda3\lib\site-packages\flask\app.py", line 1831, in finalize_request
    response = self.make_response(rv)
  File "C:\Users\Pittri\Anaconda3\lib\site-packages\flask\app.py", line 1982, in make_response
    reraise(TypeError, new_error, sys.exc_info()[2])
  File "C:\Users\Pittri\Anaconda3\lib\site-packages\flask\_compat.py", line 34, in reraise
    raise value.with_traceback(tb)
  File "C:\Users\Pittri\Anaconda3\lib\site-packages\flask\app.py", line 1974, in make_response
    rv = self.response_class.force_type(rv, request.environ)
  File "C:\Users\Pittri\Anaconda3\lib\site-packages\werkzeug\wrappers.py", line 921, in force_type
    response = BaseResponse(*_run_wsgi_app(response, environ))
  File "C:\Users\Pittri\Anaconda3\lib\site-packages\werkzeug\wrappers.py", line 59, in _run_wsgi_app
    return _run_wsgi_app(*args)
  File "C:\Users\Pittri\Anaconda3\lib\site-packages\werkzeug\test.py", line 923, in run_wsgi_app
    app_rv = app(environ, start_response)
TypeError: 'list' object is not callable
The view function did not return a valid response. The return type must be a string, tuple, Response instance, or WSGI callable, but it was a list.
Exception on /analysis [GET]
Traceback (most recent call last):
  File "C:\Users\Pittri\Anaconda3\lib\site-packages\flask\app.py", line 2292, in wsgi_app
    response = self.full_dispatch_request()
  File "C:\Users\Pittri\Anaconda3\lib\site-packages\flask\app.py", line 1815, in full_dispatch_request
    rv = self.handle_user_exception(e)
  File "C:\Users\Pittri\Anaconda3\lib\site-packages\flask\app.py", line 1718, in handle_user_exception
    reraise(exc_type, exc_value, tb)
  File "C:\Users\Pittri\Anaconda3\lib\site-packages\flask\_compat.py", line 35, in reraise
    raise value
  File "C:\Users\Pittri\Anaconda3\lib\site-packages\flask\app.py", line 1813, in full_dispatch_request
    rv = self.dispatch_request()
  File "C:\Users\Pittri\Anaconda3\lib\site-packages\flask\app.py", line 1799, in dispatch_request
    return self.view_functions[rule.endpoint](**req.view_args)
  File "sa.py", line 95, in analysis
    text = preprocessing.removePunctuation(extracted)
  File "E:\inre01\inre\preprocessing.py", line 55, in removePunctuation
    textList = li.replace(punct, " ")
AttributeError: 'list' object has no attribute 'replace'
Exception on /analysis [GET]
Traceback (most recent call last):
  File "C:\Users\Pittri\Anaconda3\lib\site-packages\flask\app.py", line 1974, in make_response
    rv = self.response_class.force_type(rv, request.environ)
  File "C:\Users\Pittri\Anaconda3\lib\site-packages\werkzeug\wrappers.py", line 921, in force_type
    response = BaseResponse(*_run_wsgi_app(response, environ))
  File "C:\Users\Pittri\Anaconda3\lib\site-packages\werkzeug\wrappers.py", line 59, in _run_wsgi_app
    return _run_wsgi_app(*args)
  File "C:\Users\Pittri\Anaconda3\lib\site-packages\werkzeug\test.py", line 923, in run_wsgi_app
    app_rv = app(environ, start_response)
TypeError: 'list' object is not callable

During handling of the above exception, another exception occurred:

Traceback (most recent call last):
  File "C:\Users\Pittri\Anaconda3\lib\site-packages\flask\app.py", line 2292, in wsgi_app
    response = self.full_dispatch_request()
  File "C:\Users\Pittri\Anaconda3\lib\site-packages\flask\app.py", line 1816, in full_dispatch_request
    return self.finalize_request(rv)
  File "C:\Users\Pittri\Anaconda3\lib\site-packages\flask\app.py", line 1831, in finalize_request
    response = self.make_response(rv)
  File "C:\Users\Pittri\Anaconda3\lib\site-packages\flask\app.py", line 1982, in make_response
    reraise(TypeError, new_error, sys.exc_info()[2])
  File "C:\Users\Pittri\Anaconda3\lib\site-packages\flask\_compat.py", line 34, in reraise
    raise value.with_traceback(tb)
  File "C:\Users\Pittri\Anaconda3\lib\site-packages\flask\app.py", line 1974, in make_response
    rv = self.response_class.force_type(rv, request.environ)
  File "C:\Users\Pittri\Anaconda3\lib\site-packages\werkzeug\wrappers.py", line 921, in force_type
    response = BaseResponse(*_run_wsgi_app(response, environ))
  File "C:\Users\Pittri\Anaconda3\lib\site-packages\werkzeug\wrappers.py", line 59, in _run_wsgi_app
    return _run_wsgi_app(*args)
  File "C:\Users\Pittri\Anaconda3\lib\site-packages\werkzeug\test.py", line 923, in run_wsgi_app
    app_rv = app(environ, start_response)
TypeError: 'list' object is not callable
The view function did not return a valid response. The return type must be a string, tuple, Response instance, or WSGI callable, but it was a list.
Exception on /analysis [GET]
Traceback (most recent call last):
  File "C:\Users\Pittri\Anaconda3\lib\site-packages\flask\app.py", line 1974, in make_response
    rv = self.response_class.force_type(rv, request.environ)
  File "C:\Users\Pittri\Anaconda3\lib\site-packages\werkzeug\wrappers.py", line 921, in force_type
    response = BaseResponse(*_run_wsgi_app(response, environ))
  File "C:\Users\Pittri\Anaconda3\lib\site-packages\werkzeug\wrappers.py", line 59, in _run_wsgi_app
    return _run_wsgi_app(*args)
  File "C:\Users\Pittri\Anaconda3\lib\site-packages\werkzeug\test.py", line 923, in run_wsgi_app
    app_rv = app(environ, start_response)
TypeError: 'list' object is not callable

During handling of the above exception, another exception occurred:

Traceback (most recent call last):
  File "C:\Users\Pittri\Anaconda3\lib\site-packages\flask\app.py", line 2292, in wsgi_app
    response = self.full_dispatch_request()
  File "C:\Users\Pittri\Anaconda3\lib\site-packages\flask\app.py", line 1816, in full_dispatch_request
    return self.finalize_request(rv)
  File "C:\Users\Pittri\Anaconda3\lib\site-packages\flask\app.py", line 1831, in finalize_request
    response = self.make_response(rv)
  File "C:\Users\Pittri\Anaconda3\lib\site-packages\flask\app.py", line 1982, in make_response
    reraise(TypeError, new_error, sys.exc_info()[2])
  File "C:\Users\Pittri\Anaconda3\lib\site-packages\flask\_compat.py", line 34, in reraise
    raise value.with_traceback(tb)
  File "C:\Users\Pittri\Anaconda3\lib\site-packages\flask\app.py", line 1974, in make_response
    rv = self.response_class.force_type(rv, request.environ)
  File "C:\Users\Pittri\Anaconda3\lib\site-packages\werkzeug\wrappers.py", line 921, in force_type
    response = BaseResponse(*_run_wsgi_app(response, environ))
  File "C:\Users\Pittri\Anaconda3\lib\site-packages\werkzeug\wrappers.py", line 59, in _run_wsgi_app
    return _run_wsgi_app(*args)
  File "C:\Users\Pittri\Anaconda3\lib\site-packages\werkzeug\test.py", line 923, in run_wsgi_app
    app_rv = app(environ, start_response)
TypeError: 'list' object is not callable
The view function did not return a valid response. The return type must be a string, tuple, Response instance, or WSGI callable, but it was a list.
Exception on /analysis [GET]
Traceback (most recent call last):
  File "C:\Users\Pittri\Anaconda3\lib\site-packages\flask\app.py", line 1974, in make_response
    rv = self.response_class.force_type(rv, request.environ)
  File "C:\Users\Pittri\Anaconda3\lib\site-packages\werkzeug\wrappers.py", line 921, in force_type
    response = BaseResponse(*_run_wsgi_app(response, environ))
  File "C:\Users\Pittri\Anaconda3\lib\site-packages\werkzeug\wrappers.py", line 59, in _run_wsgi_app
    return _run_wsgi_app(*args)
  File "C:\Users\Pittri\Anaconda3\lib\site-packages\werkzeug\test.py", line 923, in run_wsgi_app
    app_rv = app(environ, start_response)
TypeError: 'list' object is not callable

During handling of the above exception, another exception occurred:

Traceback (most recent call last):
  File "C:\Users\Pittri\Anaconda3\lib\site-packages\flask\app.py", line 2292, in wsgi_app
    response = self.full_dispatch_request()
  File "C:\Users\Pittri\Anaconda3\lib\site-packages\flask\app.py", line 1816, in full_dispatch_request
    return self.finalize_request(rv)
  File "C:\Users\Pittri\Anaconda3\lib\site-packages\flask\app.py", line 1831, in finalize_request
    response = self.make_response(rv)
  File "C:\Users\Pittri\Anaconda3\lib\site-packages\flask\app.py", line 1982, in make_response
    reraise(TypeError, new_error, sys.exc_info()[2])
  File "C:\Users\Pittri\Anaconda3\lib\site-packages\flask\_compat.py", line 34, in reraise
    raise value.with_traceback(tb)
  File "C:\Users\Pittri\Anaconda3\lib\site-packages\flask\app.py", line 1974, in make_response
    rv = self.response_class.force_type(rv, request.environ)
  File "C:\Users\Pittri\Anaconda3\lib\site-packages\werkzeug\wrappers.py", line 921, in force_type
    response = BaseResponse(*_run_wsgi_app(response, environ))
  File "C:\Users\Pittri\Anaconda3\lib\site-packages\werkzeug\wrappers.py", line 59, in _run_wsgi_app
    return _run_wsgi_app(*args)
  File "C:\Users\Pittri\Anaconda3\lib\site-packages\werkzeug\test.py", line 923, in run_wsgi_app
    app_rv = app(environ, start_response)
TypeError: 'list' object is not callable
The view function did not return a valid response. The return type must be a string, tuple, Response instance, or WSGI callable, but it was a list.
Exception on /analysis [GET]
Traceback (most recent call last):
  File "C:\Users\Pittri\Anaconda3\lib\site-packages\flask\app.py", line 1974, in make_response
    rv = self.response_class.force_type(rv, request.environ)
  File "C:\Users\Pittri\Anaconda3\lib\site-packages\werkzeug\wrappers.py", line 921, in force_type
    response = BaseResponse(*_run_wsgi_app(response, environ))
  File "C:\Users\Pittri\Anaconda3\lib\site-packages\werkzeug\test.py", line 923, in run_wsgi_app
    app_rv = app(environ, start_response)
TypeError: 'list' object is not callable

During handling of the above exception, another exception occurred:

Traceback (most recent call last):
  File "C:\Users\Pittri\Anaconda3\lib\site-packages\flask\app.py", line 2292, in wsgi_app
    response = self.full_dispatch_request()
  File "C:\Users\Pittri\Anaconda3\lib\site-packages\flask\app.py", line 1816, in full_dispatch_request
    return self.finalize_request(rv)
  File "C:\Users\Pittri\Anaconda3\lib\site-packages\flask\app.py", line 1831, in finalize_request
    response = self.make_response(rv)
  File "C:\Users\Pittri\Anaconda3\lib\site-packages\flask\app.py", line 1982, in make_response
    reraise(TypeError, new_error, sys.exc_info()[2])
  File "C:\Users\Pittri\Anaconda3\lib\site-packages\flask\_compat.py", line 34, in reraise
    raise value.with_traceback(tb)
  File "C:\Users\Pittri\Anaconda3\lib\site-packages\flask\app.py", line 1974, in make_response
    rv = self.response_class.force_type(rv, request.environ)
  File "C:\Users\Pittri\Anaconda3\lib\site-packages\werkzeug\wrappers.py", line 921, in force_type
    response = BaseResponse(*_run_wsgi_app(response, environ))
  File "C:\Users\Pittri\Anaconda3\lib\site-packages\werkzeug\test.py", line 923, in run_wsgi_app
    app_rv = app(environ, start_response)
TypeError: 'list' object is not callable
The view function did not return a valid response. The return type must be a string, tuple, Response instance, or WSGI callable, but it was a list.
Exception on /analysis [GET]
Traceback (most recent call last):
  File "C:\Users\Pittri\Anaconda3\lib\site-packages\flask\app.py", line 1974, in make_response
    rv = self.response_class.force_type(rv, request.environ)
  File "C:\Users\Pittri\Anaconda3\lib\site-packages\werkzeug\wrappers.py", line 921, in force_type
    response = BaseResponse(*_run_wsgi_app(response, environ))
  File "C:\Users\Pittri\Anaconda3\lib\site-packages\werkzeug\wrappers.py", line 59, in _run_wsgi_app
    return _run_wsgi_app(*args)
  File "C:\Users\Pittri\Anaconda3\lib\site-packages\werkzeug\test.py", line 923, in run_wsgi_app
    app_rv = app(environ, start_response)
TypeError: 'list' object is not callable

During handling of the above exception, another exception occurred:

Traceback (most recent call last):
  File "C:\Users\Pittri\Anaconda3\lib\site-packages\flask\app.py", line 2292, in wsgi_app
    response = self.full_dispatch_request()
  File "C:\Users\Pittri\Anaconda3\lib\site-packages\flask\app.py", line 1816, in full_dispatch_request
    return self.finalize_request(rv)
  File "C:\Users\Pittri\Anaconda3\lib\site-packages\flask\app.py", line 1831, in finalize_request
    response = self.make_response(rv)
  File "C:\Users\Pittri\Anaconda3\lib\site-packages\flask\app.py", line 1982, in make_response
    reraise(TypeError, new_error, sys.exc_info()[2])
  File "C:\Users\Pittri\Anaconda3\lib\site-packages\flask\_compat.py", line 34, in reraise
    raise value.with_traceback(tb)
  File "C:\Users\Pittri\Anaconda3\lib\site-packages\flask\app.py", line 1974, in make_response
    rv = self.response_class.force_type(rv, request.environ)
  File "C:\Users\Pittri\Anaconda3\lib\site-packages\werkzeug\wrappers.py", line 921, in force_type
    response = BaseResponse(*_run_wsgi_app(response, environ))
  File "C:\Users\Pittri\Anaconda3\lib\site-packages\werkzeug\wrappers.py", line 59, in _run_wsgi_app
    return _run_wsgi_app(*args)
  File "C:\Users\Pittri\Anaconda3\lib\site-packages\werkzeug\test.py", line 923, in run_wsgi_app
    app_rv = app(environ, start_response)
TypeError: 'list' object is not callable
The view function did not return a valid response. The return type must be a string, tuple, Response instance, or WSGI callable, but it was a list.
Exception on /analysis [GET]
Traceback (most recent call last):
  File "C:\Users\Pittri\Anaconda3\lib\site-packages\flask\app.py", line 1974, in make_response
    rv = self.response_class.force_type(rv, request.environ)
  File "C:\Users\Pittri\Anaconda3\lib\site-packages\werkzeug\wrappers.py", line 921, in force_type
    response = BaseResponse(*_run_wsgi_app(response, environ))
  File "C:\Users\Pittri\Anaconda3\lib\site-packages\werkzeug\wrappers.py", line 59, in _run_wsgi_app
    return _run_wsgi_app(*args)
  File "C:\Users\Pittri\Anaconda3\lib\site-packages\werkzeug\test.py", line 923, in run_wsgi_app
    app_rv = app(environ, start_response)
TypeError: 'list' object is not callable

During handling of the above exception, another exception occurred:

Traceback (most recent call last):
  File "C:\Users\Pittri\Anaconda3\lib\site-packages\flask\app.py", line 2292, in wsgi_app
    response = self.full_dispatch_request()
  File "C:\Users\Pittri\Anaconda3\lib\site-packages\flask\app.py", line 1816, in full_dispatch_request
    return self.finalize_request(rv)
  File "C:\Users\Pittri\Anaconda3\lib\site-packages\flask\app.py", line 1831, in finalize_request
    response = self.make_response(rv)
  File "C:\Users\Pittri\Anaconda3\lib\site-packages\flask\app.py", line 1982, in make_response
    reraise(TypeError, new_error, sys.exc_info()[2])
  File "C:\Users\Pittri\Anaconda3\lib\site-packages\flask\_compat.py", line 34, in reraise
    raise value.with_traceback(tb)
  File "C:\Users\Pittri\Anaconda3\lib\site-packages\flask\app.py", line 1974, in make_response
    rv = self.response_class.force_type(rv, request.environ)
  File "C:\Users\Pittri\Anaconda3\lib\site-packages\werkzeug\wrappers.py", line 921, in force_type
    response = BaseResponse(*_run_wsgi_app(response, environ))
  File "C:\Users\Pittri\Anaconda3\lib\site-packages\werkzeug\wrappers.py", line 59, in _run_wsgi_app
    return _run_wsgi_app(*args)
  File "C:\Users\Pittri\Anaconda3\lib\site-packages\werkzeug\test.py", line 923, in run_wsgi_app
    app_rv = app(environ, start_response)
TypeError: 'list' object is not callable
The view function did not return a valid response. The return type must be a string, tuple, Response instance, or WSGI callable, but it was a list.
Exception on /analysis [GET]
Traceback (most recent call last):
  File "C:\Users\Pittri\Anaconda3\lib\site-packages\flask\app.py", line 1974, in make_response
    rv = self.response_class.force_type(rv, request.environ)
  File "C:\Users\Pittri\Anaconda3\lib\site-packages\werkzeug\wrappers.py", line 921, in force_type
    response = BaseResponse(*_run_wsgi_app(response, environ))
  File "C:\Users\Pittri\Anaconda3\lib\site-packages\werkzeug\wrappers.py", line 59, in _run_wsgi_app
    return _run_wsgi_app(*args)
  File "C:\Users\Pittri\Anaconda3\lib\site-packages\werkzeug\test.py", line 923, in run_wsgi_app
    app_rv = app(environ, start_response)
TypeError: 'list' object is not callable

During handling of the above exception, another exception occurred:

Traceback (most recent call last):
  File "C:\Users\Pittri\Anaconda3\lib\site-packages\flask\app.py", line 2292, in wsgi_app
    response = self.full_dispatch_request()
  File "C:\Users\Pittri\Anaconda3\lib\site-packages\flask\app.py", line 1816, in full_dispatch_request
    return self.finalize_request(rv)
  File "C:\Users\Pittri\Anaconda3\lib\site-packages\flask\app.py", line 1831, in finalize_request
    response = self.make_response(rv)
  File "C:\Users\Pittri\Anaconda3\lib\site-packages\flask\app.py", line 1982, in make_response
    reraise(TypeError, new_error, sys.exc_info()[2])
  File "C:\Users\Pittri\Anaconda3\lib\site-packages\flask\_compat.py", line 34, in reraise
    raise value.with_traceback(tb)
  File "C:\Users\Pittri\Anaconda3\lib\site-packages\flask\app.py", line 1974, in make_response
    rv = self.response_class.force_type(rv, request.environ)
  File "C:\Users\Pittri\Anaconda3\lib\site-packages\werkzeug\wrappers.py", line 921, in force_type
    response = BaseResponse(*_run_wsgi_app(response, environ))
  File "C:\Users\Pittri\Anaconda3\lib\site-packages\werkzeug\wrappers.py", line 59, in _run_wsgi_app
    return _run_wsgi_app(*args)
  File "C:\Users\Pittri\Anaconda3\lib\site-packages\werkzeug\test.py", line 923, in run_wsgi_app
    app_rv = app(environ, start_response)
TypeError: 'list' object is not callable
The view function did not return a valid response. The return type must be a string, tuple, Response instance, or WSGI callable, but it was a list.
Exception on /analysis [GET]
Traceback (most recent call last):
  File "C:\Users\Pittri\Anaconda3\lib\site-packages\flask\app.py", line 1974, in make_response
    rv = self.response_class.force_type(rv, request.environ)
  File "C:\Users\Pittri\Anaconda3\lib\site-packages\werkzeug\wrappers.py", line 921, in force_type
    response = BaseResponse(*_run_wsgi_app(response, environ))
  File "C:\Users\Pittri\Anaconda3\lib\site-packages\werkzeug\wrappers.py", line 59, in _run_wsgi_app
    return _run_wsgi_app(*args)
  File "C:\Users\Pittri\Anaconda3\lib\site-packages\werkzeug\test.py", line 923, in run_wsgi_app
    app_rv = app(environ, start_response)
TypeError: 'list' object is not callable

During handling of the above exception, another exception occurred:

Traceback (most recent call last):
  File "C:\Users\Pittri\Anaconda3\lib\site-packages\flask\app.py", line 2292, in wsgi_app
    response = self.full_dispatch_request()
  File "C:\Users\Pittri\Anaconda3\lib\site-packages\flask\app.py", line 1816, in full_dispatch_request
    return self.finalize_request(rv)
  File "C:\Users\Pittri\Anaconda3\lib\site-packages\flask\app.py", line 1831, in finalize_request
    response = self.make_response(rv)
  File "C:\Users\Pittri\Anaconda3\lib\site-packages\flask\app.py", line 1982, in make_response
    reraise(TypeError, new_error, sys.exc_info()[2])
  File "C:\Users\Pittri\Anaconda3\lib\site-packages\flask\_compat.py", line 34, in reraise
    raise value.with_traceback(tb)
  File "C:\Users\Pittri\Anaconda3\lib\site-packages\flask\app.py", line 1974, in make_response
    rv = self.response_class.force_type(rv, request.environ)
  File "C:\Users\Pittri\Anaconda3\lib\site-packages\werkzeug\wrappers.py", line 921, in force_type
    response = BaseResponse(*_run_wsgi_app(response, environ))
  File "C:\Users\Pittri\Anaconda3\lib\site-packages\werkzeug\wrappers.py", line 59, in _run_wsgi_app
    return _run_wsgi_app(*args)
  File "C:\Users\Pittri\Anaconda3\lib\site-packages\werkzeug\test.py", line 923, in run_wsgi_app
    app_rv = app(environ, start_response)
TypeError: 'list' object is not callable
The view function did not return a valid response. The return type must be a string, tuple, Response instance, or WSGI callable, but it was a list.
Exception on /analysis [GET]
Traceback (most recent call last):
  File "C:\Users\Pittri\Anaconda3\lib\site-packages\flask\app.py", line 2292, in wsgi_app
    response = self.full_dispatch_request()
  File "C:\Users\Pittri\Anaconda3\lib\site-packages\flask\app.py", line 1815, in full_dispatch_request
    rv = self.handle_user_exception(e)
  File "C:\Users\Pittri\Anaconda3\lib\site-packages\flask\app.py", line 1718, in handle_user_exception
    reraise(exc_type, exc_value, tb)
  File "C:\Users\Pittri\Anaconda3\lib\site-packages\flask\_compat.py", line 35, in reraise
    raise value
  File "C:\Users\Pittri\Anaconda3\lib\site-packages\flask\app.py", line 1813, in full_dispatch_request
    rv = self.dispatch_request()
  File "C:\Users\Pittri\Anaconda3\lib\site-packages\flask\app.py", line 1799, in dispatch_request
    return self.view_functions[rule.endpoint](**req.view_args)
  File "sa.py", line 112, in analysis
    query = preprocessing.removePunctuation(query_search)
  File "E:\inre01\inre\preprocessing.py", line 52, in removePunctuation
    textList[i] = textList[i].replace(punct, " ")
TypeError: 'str' object does not support item assignment
Exception on /analysis [GET]
Traceback (most recent call last):
  File "C:\Users\Pittri\Anaconda3\lib\site-packages\flask\app.py", line 2292, in wsgi_app
    response = self.full_dispatch_request()
  File "C:\Users\Pittri\Anaconda3\lib\site-packages\flask\app.py", line 1815, in full_dispatch_request
    rv = self.handle_user_exception(e)
  File "C:\Users\Pittri\Anaconda3\lib\site-packages\flask\app.py", line 1718, in handle_user_exception
    reraise(exc_type, exc_value, tb)
  File "C:\Users\Pittri\Anaconda3\lib\site-packages\flask\_compat.py", line 35, in reraise
    raise value
  File "C:\Users\Pittri\Anaconda3\lib\site-packages\flask\app.py", line 1813, in full_dispatch_request
    rv = self.dispatch_request()
  File "C:\Users\Pittri\Anaconda3\lib\site-packages\flask\app.py", line 1799, in dispatch_request
    return self.view_functions[rule.endpoint](**req.view_args)
  File "sa.py", line 112, in analysis
    query = preprocessing.removePunctuation(query_search)
  File "E:\inre01\inre\preprocessing.py", line 52, in removePunctuation
    textList[i] = textList[i].replace(punct, " ")
TypeError: 'str' object does not support item assignment
Exception on /analysis [GET]
Traceback (most recent call last):
  File "C:\Users\Pittri\Anaconda3\lib\site-packages\flask\app.py", line 2292, in wsgi_app
    response = self.full_dispatch_request()
  File "C:\Users\Pittri\Anaconda3\lib\site-packages\flask\app.py", line 1815, in full_dispatch_request
    rv = self.handle_user_exception(e)
  File "C:\Users\Pittri\Anaconda3\lib\site-packages\flask\app.py", line 1718, in handle_user_exception
    reraise(exc_type, exc_value, tb)
  File "C:\Users\Pittri\Anaconda3\lib\site-packages\flask\_compat.py", line 35, in reraise
    raise value
  File "C:\Users\Pittri\Anaconda3\lib\site-packages\flask\app.py", line 1813, in full_dispatch_request
    rv = self.dispatch_request()
  File "C:\Users\Pittri\Anaconda3\lib\site-packages\flask\app.py", line 1799, in dispatch_request
    return self.view_functions[rule.endpoint](**req.view_args)
  File "sa.py", line 112, in analysis
    query = preprocessing.removePunctuation(query_search)
  File "E:\inre01\inre\preprocessing.py", line 52, in removePunctuation
    textList[i] = textList[i].replace(punct, " ")
TypeError: 'str' object does not support item assignment
Exception on /analysis [GET]
Traceback (most recent call last):
  File "C:\Users\Pittri\Anaconda3\lib\site-packages\flask\app.py", line 2292, in wsgi_app
    response = self.full_dispatch_request()
  File "C:\Users\Pittri\Anaconda3\lib\site-packages\flask\app.py", line 1815, in full_dispatch_request
    rv = self.handle_user_exception(e)
  File "C:\Users\Pittri\Anaconda3\lib\site-packages\flask\app.py", line 1718, in handle_user_exception
    reraise(exc_type, exc_value, tb)
  File "C:\Users\Pittri\Anaconda3\lib\site-packages\flask\_compat.py", line 35, in reraise
    raise value
  File "C:\Users\Pittri\Anaconda3\lib\site-packages\flask\app.py", line 1813, in full_dispatch_request
    rv = self.dispatch_request()
  File "C:\Users\Pittri\Anaconda3\lib\site-packages\flask\app.py", line 1799, in dispatch_request
    return self.view_functions[rule.endpoint](**req.view_args)
  File "process.py", line 112, in analysis
    query = preprocessing.removePunctuation(query_search)
  File "E:\inre01\Query Expansion pada Biografi\preprocessing.py", line 52, in removePunctuation
    textList[i] = textList[i].replace(punct, " ")
TypeError: 'str' object does not support item assignment
Exception on /analysis [GET]
Traceback (most recent call last):
  File "C:\Users\Pittri\Anaconda3\lib\site-packages\flask\app.py", line 2292, in wsgi_app
    response = self.full_dispatch_request()
  File "C:\Users\Pittri\Anaconda3\lib\site-packages\flask\app.py", line 1815, in full_dispatch_request
    rv = self.handle_user_exception(e)
  File "C:\Users\Pittri\Anaconda3\lib\site-packages\flask\app.py", line 1718, in handle_user_exception
    reraise(exc_type, exc_value, tb)
  File "C:\Users\Pittri\Anaconda3\lib\site-packages\flask\_compat.py", line 35, in reraise
    raise value
  File "C:\Users\Pittri\Anaconda3\lib\site-packages\flask\app.py", line 1813, in full_dispatch_request
    rv = self.dispatch_request()
  File "C:\Users\Pittri\Anaconda3\lib\site-packages\flask\app.py", line 1799, in dispatch_request
    return self.view_functions[rule.endpoint](**req.view_args)
  File "process.py", line 112, in analysis
    query = preprocessing.removePunctuation(query_search)
  File "E:\inre01\Query Expansion pada Biografi\preprocessing.py", line 52, in removePunctuation
    textList[i] = textList[i].replace(punct, " ")
TypeError: 'str' object does not support item assignment
Exception on /analysis [GET]
Traceback (most recent call last):
  File "C:\Users\Pittri\Anaconda3\lib\site-packages\flask\app.py", line 2292, in wsgi_app
    response = self.full_dispatch_request()
  File "C:\Users\Pittri\Anaconda3\lib\site-packages\flask\app.py", line 1815, in full_dispatch_request
    rv = self.handle_user_exception(e)
  File "C:\Users\Pittri\Anaconda3\lib\site-packages\flask\app.py", line 1718, in handle_user_exception
    reraise(exc_type, exc_value, tb)
  File "C:\Users\Pittri\Anaconda3\lib\site-packages\flask\_compat.py", line 35, in reraise
    raise value
  File "C:\Users\Pittri\Anaconda3\lib\site-packages\flask\app.py", line 1813, in full_dispatch_request
    rv = self.dispatch_request()
  File "C:\Users\Pittri\Anaconda3\lib\site-packages\flask\app.py", line 1799, in dispatch_request
    return self.view_functions[rule.endpoint](**req.view_args)
  File "process.py", line 158, in analysis
    query = preprocessing.removePunctuation(query_search)
  File "E:\inre01\Query Expansion pada Biografi\preprocessing.py", line 52, in removePunctuation
    textList[i] = textList[i].replace(punct, " ")
TypeError: 'str' object does not support item assignment
Exception on /analysis [GET]
Traceback (most recent call last):
  File "C:\Users\Pittri\Anaconda3\lib\site-packages\flask\app.py", line 2292, in wsgi_app
    response = self.full_dispatch_request()
  File "C:\Users\Pittri\Anaconda3\lib\site-packages\flask\app.py", line 1815, in full_dispatch_request
    rv = self.handle_user_exception(e)
  File "C:\Users\Pittri\Anaconda3\lib\site-packages\flask\app.py", line 1718, in handle_user_exception
    reraise(exc_type, exc_value, tb)
  File "C:\Users\Pittri\Anaconda3\lib\site-packages\flask\_compat.py", line 35, in reraise
    raise value
  File "C:\Users\Pittri\Anaconda3\lib\site-packages\flask\app.py", line 1813, in full_dispatch_request
    rv = self.dispatch_request()
  File "C:\Users\Pittri\Anaconda3\lib\site-packages\flask\app.py", line 1799, in dispatch_request
    return self.view_functions[rule.endpoint](**req.view_args)
  File "process.py", line 158, in analysis
    query = preprocessing.removePunctuation(query_search)
  File "E:\inre01\Query Expansion pada Biografi\preprocessing.py", line 52, in removePunctuation
    textList[i] = textList[i].replace(punct, " ")
TypeError: 'str' object does not support item assignment
Exception on /analysis [GET]
Traceback (most recent call last):
  File "C:\Users\Pittri\Anaconda3\lib\site-packages\flask\app.py", line 2292, in wsgi_app
    response = self.full_dispatch_request()
  File "C:\Users\Pittri\Anaconda3\lib\site-packages\flask\app.py", line 1815, in full_dispatch_request
    rv = self.handle_user_exception(e)
  File "C:\Users\Pittri\Anaconda3\lib\site-packages\flask\app.py", line 1718, in handle_user_exception
    reraise(exc_type, exc_value, tb)
  File "C:\Users\Pittri\Anaconda3\lib\site-packages\flask\_compat.py", line 35, in reraise
    raise value
  File "C:\Users\Pittri\Anaconda3\lib\site-packages\flask\app.py", line 1813, in full_dispatch_request
    rv = self.dispatch_request()
  File "C:\Users\Pittri\Anaconda3\lib\site-packages\flask\app.py", line 1799, in dispatch_request
    return self.view_functions[rule.endpoint](**req.view_args)
  File "process.py", line 158, in analysis
    query = preprocessing.removePunctuation(query_search)
  File "E:\inre01\Query Expansion pada Biografi\preprocessing.py", line 52, in removePunctuation
    textList[i] = textList[i].replace(punct, " ")
TypeError: 'str' object does not support item assignment
Exception on /analysis [GET]
Traceback (most recent call last):
  File "C:\Users\Pittri\Anaconda3\lib\site-packages\flask\app.py", line 2292, in wsgi_app
    response = self.full_dispatch_request()
  File "C:\Users\Pittri\Anaconda3\lib\site-packages\flask\app.py", line 1815, in full_dispatch_request
    rv = self.handle_user_exception(e)
  File "C:\Users\Pittri\Anaconda3\lib\site-packages\flask\app.py", line 1718, in handle_user_exception
    reraise(exc_type, exc_value, tb)
  File "C:\Users\Pittri\Anaconda3\lib\site-packages\flask\_compat.py", line 35, in reraise
    raise value
  File "C:\Users\Pittri\Anaconda3\lib\site-packages\flask\app.py", line 1813, in full_dispatch_request
    rv = self.dispatch_request()
  File "C:\Users\Pittri\Anaconda3\lib\site-packages\flask\app.py", line 1799, in dispatch_request
    return self.view_functions[rule.endpoint](**req.view_args)
  File "process.py", line 137, in analysis
    return render_template('Load Berhasil')
  File "C:\Users\Pittri\Anaconda3\lib\site-packages\flask\templating.py", line 134, in render_template
    return _render(ctx.app.jinja_env.get_or_select_template(template_name_or_list),
  File "C:\Users\Pittri\Anaconda3\lib\site-packages\jinja2\environment.py", line 869, in get_or_select_template
    return self.get_template(template_name_or_list, parent, globals)
  File "C:\Users\Pittri\Anaconda3\lib\site-packages\jinja2\environment.py", line 830, in get_template
    return self._load_template(name, self.make_globals(globals))
  File "C:\Users\Pittri\Anaconda3\lib\site-packages\jinja2\environment.py", line 804, in _load_template
    template = self.loader.load(self, name, globals)
  File "C:\Users\Pittri\Anaconda3\lib\site-packages\jinja2\loaders.py", line 113, in load
    source, filename, uptodate = self.get_source(environment, name)
  File "C:\Users\Pittri\Anaconda3\lib\site-packages\flask\templating.py", line 58, in get_source
    return self._get_source_fast(environment, template)
  File "C:\Users\Pittri\Anaconda3\lib\site-packages\flask\templating.py", line 86, in _get_source_fast
    raise TemplateNotFound(template)
jinja2.exceptions.TemplateNotFound: Load Berhasil
Exception on /analysis [GET]
Traceback (most recent call last):
  File "C:\Users\Pittri\Anaconda3\lib\site-packages\flask\app.py", line 2292, in wsgi_app
    response = self.full_dispatch_request()
  File "C:\Users\Pittri\Anaconda3\lib\site-packages\flask\app.py", line 1815, in full_dispatch_request
    rv = self.handle_user_exception(e)
  File "C:\Users\Pittri\Anaconda3\lib\site-packages\flask\app.py", line 1718, in handle_user_exception
    reraise(exc_type, exc_value, tb)
  File "C:\Users\Pittri\Anaconda3\lib\site-packages\flask\_compat.py", line 35, in reraise
    raise value
  File "C:\Users\Pittri\Anaconda3\lib\site-packages\flask\app.py", line 1813, in full_dispatch_request
    rv = self.dispatch_request()
  File "C:\Users\Pittri\Anaconda3\lib\site-packages\flask\app.py", line 1799, in dispatch_request
    return self.view_functions[rule.endpoint](**req.view_args)
  File "process.py", line 163, in analysis
    query = preprocessing.removePunctuation(query_search)
  File "E:\inre01\Query Expansion pada Biografi\preprocessing.py", line 52, in removePunctuation
    textList[i] = textList[i].replace(punct, " ")
TypeError: 'str' object does not support item assignment
Exception on /analysis [GET]
Traceback (most recent call last):
  File "C:\Users\Pittri\Anaconda3\lib\site-packages\flask\app.py", line 2292, in wsgi_app
    response = self.full_dispatch_request()
  File "C:\Users\Pittri\Anaconda3\lib\site-packages\flask\app.py", line 1815, in full_dispatch_request
    rv = self.handle_user_exception(e)
  File "C:\Users\Pittri\Anaconda3\lib\site-packages\flask\app.py", line 1718, in handle_user_exception
    reraise(exc_type, exc_value, tb)
  File "C:\Users\Pittri\Anaconda3\lib\site-packages\flask\_compat.py", line 35, in reraise
    raise value
  File "C:\Users\Pittri\Anaconda3\lib\site-packages\flask\app.py", line 1813, in full_dispatch_request
    rv = self.dispatch_request()
  File "C:\Users\Pittri\Anaconda3\lib\site-packages\flask\app.py", line 1799, in dispatch_request
    return self.view_functions[rule.endpoint](**req.view_args)
  File "process.py", line 164, in analysis
    query = preprocessing.removePunctuation(query_search)
  File "E:\inre01\Query Expansion pada Biografi\preprocessing.py", line 52, in removePunctuation
    textList[i] = textList[i].replace(punct, " ")
TypeError: 'str' object does not support item assignment
Exception on /analysis [GET]
Traceback (most recent call last):
  File "C:\Users\Pittri\Anaconda3\lib\site-packages\flask\app.py", line 2292, in wsgi_app
    response = self.full_dispatch_request()
  File "C:\Users\Pittri\Anaconda3\lib\site-packages\flask\app.py", line 1815, in full_dispatch_request
    rv = self.handle_user_exception(e)
  File "C:\Users\Pittri\Anaconda3\lib\site-packages\flask\app.py", line 1718, in handle_user_exception
    reraise(exc_type, exc_value, tb)
  File "C:\Users\Pittri\Anaconda3\lib\site-packages\flask\_compat.py", line 35, in reraise
    raise value
  File "C:\Users\Pittri\Anaconda3\lib\site-packages\flask\app.py", line 1813, in full_dispatch_request
    rv = self.dispatch_request()
  File "C:\Users\Pittri\Anaconda3\lib\site-packages\flask\app.py", line 1799, in dispatch_request
    return self.view_functions[rule.endpoint](**req.view_args)
  File "process.py", line 164, in analysis
    query = preprocessing.removePunct(query_search)
AttributeError: module 'preprocessing' has no attribute 'removePunct'
Exception on /analysis [GET]
Traceback (most recent call last):
  File "C:\Users\Pittri\Anaconda3\lib\site-packages\flask\app.py", line 2292, in wsgi_app
    response = self.full_dispatch_request()
  File "C:\Users\Pittri\Anaconda3\lib\site-packages\flask\app.py", line 1815, in full_dispatch_request
    rv = self.handle_user_exception(e)
  File "C:\Users\Pittri\Anaconda3\lib\site-packages\flask\app.py", line 1718, in handle_user_exception
    reraise(exc_type, exc_value, tb)
  File "C:\Users\Pittri\Anaconda3\lib\site-packages\flask\_compat.py", line 35, in reraise
    raise value
  File "C:\Users\Pittri\Anaconda3\lib\site-packages\flask\app.py", line 1813, in full_dispatch_request
    rv = self.dispatch_request()
  File "C:\Users\Pittri\Anaconda3\lib\site-packages\flask\app.py", line 1799, in dispatch_request
    return self.view_functions[rule.endpoint](**req.view_args)
  File "process.py", line 164, in analysis
    query = preprocessing.removePunct(query_search)
AttributeError: module 'preprocessing' has no attribute 'removePunct'
Exception on /analysis [GET]
Traceback (most recent call last):
  File "C:\Users\Pittri\Anaconda3\lib\site-packages\flask\app.py", line 2292, in wsgi_app
    response = self.full_dispatch_request()
  File "C:\Users\Pittri\Anaconda3\lib\site-packages\flask\app.py", line 1815, in full_dispatch_request
    rv = self.handle_user_exception(e)
  File "C:\Users\Pittri\Anaconda3\lib\site-packages\flask\app.py", line 1718, in handle_user_exception
    reraise(exc_type, exc_value, tb)
  File "C:\Users\Pittri\Anaconda3\lib\site-packages\flask\_compat.py", line 35, in reraise
    raise value
  File "C:\Users\Pittri\Anaconda3\lib\site-packages\flask\app.py", line 1813, in full_dispatch_request
    rv = self.dispatch_request()
  File "C:\Users\Pittri\Anaconda3\lib\site-packages\flask\app.py", line 1799, in dispatch_request
    return self.view_functions[rule.endpoint](**req.view_args)
  File "process.py", line 167, in analysis
    query = preprocessing.tokeniz(query)
  File "E:\inre01\Query Expansion pada Biografi\preprocessing.py", line 91, in tokeniz
    tokens.append(token(textList))
  File "E:\inre01\Query Expansion pada Biografi\preprocessing.py", line 78, in token
    for word in CountVectorizer().build_tokenizer()(sentence):
  File "C:\Users\Pittri\Anaconda3\lib\site-packages\sklearn\feature_extraction\text.py", line 266, in <lambda>
    return lambda doc: token_pattern.findall(doc)
TypeError: expected string or bytes-like object
Exception on /analysis [GET]
Traceback (most recent call last):
  File "C:\Users\Pittri\Anaconda3\lib\site-packages\flask\app.py", line 2292, in wsgi_app
    response = self.full_dispatch_request()
  File "C:\Users\Pittri\Anaconda3\lib\site-packages\flask\app.py", line 1815, in full_dispatch_request
    rv = self.handle_user_exception(e)
  File "C:\Users\Pittri\Anaconda3\lib\site-packages\flask\app.py", line 1718, in handle_user_exception
    reraise(exc_type, exc_value, tb)
  File "C:\Users\Pittri\Anaconda3\lib\site-packages\flask\_compat.py", line 35, in reraise
    raise value
  File "C:\Users\Pittri\Anaconda3\lib\site-packages\flask\app.py", line 1813, in full_dispatch_request
    rv = self.dispatch_request()
  File "C:\Users\Pittri\Anaconda3\lib\site-packages\flask\app.py", line 1799, in dispatch_request
    return self.view_functions[rule.endpoint](**req.view_args)
  File "process.py", line 168, in analysis
    query = preprocessing.tokeni(query)
  File "E:\inre01\Query Expansion pada Biografi\preprocessing.py", line 84, in tokeni
    for word in CountVectorizer().build_tokenizer()(sentence):
  File "C:\Users\Pittri\Anaconda3\lib\site-packages\sklearn\feature_extraction\text.py", line 266, in <lambda>
    return lambda doc: token_pattern.findall(doc)
TypeError: expected string or bytes-like object
Exception on /analysis [GET]
Traceback (most recent call last):
  File "C:\Users\Pittri\Anaconda3\lib\site-packages\flask\app.py", line 2292, in wsgi_app
    response = self.full_dispatch_request()
  File "C:\Users\Pittri\Anaconda3\lib\site-packages\flask\app.py", line 1815, in full_dispatch_request
    rv = self.handle_user_exception(e)
  File "C:\Users\Pittri\Anaconda3\lib\site-packages\flask\app.py", line 1718, in handle_user_exception
    reraise(exc_type, exc_value, tb)
  File "C:\Users\Pittri\Anaconda3\lib\site-packages\flask\_compat.py", line 35, in reraise
    raise value
  File "C:\Users\Pittri\Anaconda3\lib\site-packages\flask\app.py", line 1813, in full_dispatch_request
    rv = self.dispatch_request()
  File "C:\Users\Pittri\Anaconda3\lib\site-packages\flask\app.py", line 1799, in dispatch_request
    return self.view_functions[rule.endpoint](**req.view_args)
  File "process.py", line 168, in analysis
    query = preprocessing.tokeni(query)
  File "E:\inre01\Query Expansion pada Biografi\preprocessing.py", line 84, in tokeni
    for word in CountVectorizer().build_tokenizer()(sentence):
  File "C:\Users\Pittri\Anaconda3\lib\site-packages\sklearn\feature_extraction\text.py", line 266, in <lambda>
    return lambda doc: token_pattern.findall(doc)
TypeError: expected string or bytes-like object
Exception on /analysis [GET]
Traceback (most recent call last):
  File "C:\Users\Pittri\Anaconda3\lib\site-packages\flask\app.py", line 2292, in wsgi_app
    response = self.full_dispatch_request()
  File "C:\Users\Pittri\Anaconda3\lib\site-packages\flask\app.py", line 1815, in full_dispatch_request
    rv = self.handle_user_exception(e)
  File "C:\Users\Pittri\Anaconda3\lib\site-packages\flask\app.py", line 1718, in handle_user_exception
    reraise(exc_type, exc_value, tb)
  File "C:\Users\Pittri\Anaconda3\lib\site-packages\flask\_compat.py", line 35, in reraise
    raise value
  File "C:\Users\Pittri\Anaconda3\lib\site-packages\flask\app.py", line 1813, in full_dispatch_request
    rv = self.dispatch_request()
  File "C:\Users\Pittri\Anaconda3\lib\site-packages\flask\app.py", line 1799, in dispatch_request
    return self.view_functions[rule.endpoint](**req.view_args)
  File "process.py", line 169, in analysis
    query = preprocessing.tokeni(query)
  File "E:\inre01\Query Expansion pada Biografi\preprocessing.py", line 86, in tokeni
    for word in CountVectorizer().build_tokenizer()(sentence):
  File "C:\Users\Pittri\Anaconda3\lib\site-packages\sklearn\feature_extraction\text.py", line 266, in <lambda>
    return lambda doc: token_pattern.findall(doc)
TypeError: expected string or bytes-like object
Exception on /analysis [GET]
Traceback (most recent call last):
  File "C:\Users\Pittri\Anaconda3\lib\site-packages\flask\app.py", line 2292, in wsgi_app
    response = self.full_dispatch_request()
  File "C:\Users\Pittri\Anaconda3\lib\site-packages\flask\app.py", line 1815, in full_dispatch_request
    rv = self.handle_user_exception(e)
  File "C:\Users\Pittri\Anaconda3\lib\site-packages\flask\app.py", line 1718, in handle_user_exception
    reraise(exc_type, exc_value, tb)
  File "C:\Users\Pittri\Anaconda3\lib\site-packages\flask\_compat.py", line 35, in reraise
    raise value
  File "C:\Users\Pittri\Anaconda3\lib\site-packages\flask\app.py", line 1813, in full_dispatch_request
    rv = self.dispatch_request()
  File "C:\Users\Pittri\Anaconda3\lib\site-packages\flask\app.py", line 1799, in dispatch_request
    return self.view_functions[rule.endpoint](**req.view_args)
  File "process.py", line 169, in analysis
    query = preprocessing.tokeni(query)
  File "E:\inre01\Query Expansion pada Biografi\preprocessing.py", line 86, in tokeni
    for word in CountVectorizer().build_tokenizer()(sentence):
  File "C:\Users\Pittri\Anaconda3\lib\site-packages\sklearn\feature_extraction\text.py", line 266, in <lambda>
    return lambda doc: token_pattern.findall(doc)
TypeError: expected string or bytes-like object
Exception on /analysis [GET]
Traceback (most recent call last):
  File "C:\Users\Pittri\Anaconda3\lib\site-packages\flask\app.py", line 2292, in wsgi_app
    response = self.full_dispatch_request()
  File "C:\Users\Pittri\Anaconda3\lib\site-packages\flask\app.py", line 1815, in full_dispatch_request
    rv = self.handle_user_exception(e)
  File "C:\Users\Pittri\Anaconda3\lib\site-packages\flask\app.py", line 1718, in handle_user_exception
    reraise(exc_type, exc_value, tb)
  File "C:\Users\Pittri\Anaconda3\lib\site-packages\flask\_compat.py", line 35, in reraise
    raise value
  File "C:\Users\Pittri\Anaconda3\lib\site-packages\flask\app.py", line 1813, in full_dispatch_request
    rv = self.dispatch_request()
  File "C:\Users\Pittri\Anaconda3\lib\site-packages\flask\app.py", line 1799, in dispatch_request
    return self.view_functions[rule.endpoint](**req.view_args)
  File "process.py", line 169, in analysis
    query = preprocessing.tokeni(query)
  File "E:\inre01\Query Expansion pada Biografi\preprocessing.py", line 86, in tokeni
    for word in CountVectorizer().build_tokenizer():
TypeError: 'function' object is not iterable
Exception on /analysis [GET]
Traceback (most recent call last):
  File "C:\Users\Pittri\Anaconda3\lib\site-packages\flask\app.py", line 2292, in wsgi_app
    response = self.full_dispatch_request()
  File "C:\Users\Pittri\Anaconda3\lib\site-packages\flask\app.py", line 1815, in full_dispatch_request
    rv = self.handle_user_exception(e)
  File "C:\Users\Pittri\Anaconda3\lib\site-packages\flask\app.py", line 1718, in handle_user_exception
    reraise(exc_type, exc_value, tb)
  File "C:\Users\Pittri\Anaconda3\lib\site-packages\flask\_compat.py", line 35, in reraise
    raise value
  File "C:\Users\Pittri\Anaconda3\lib\site-packages\flask\app.py", line 1813, in full_dispatch_request
    rv = self.dispatch_request()
  File "C:\Users\Pittri\Anaconda3\lib\site-packages\flask\app.py", line 1799, in dispatch_request
    return self.view_functions[rule.endpoint](**req.view_args)
  File "process.py", line 169, in analysis
    query = preprocessing.token(query)
  File "E:\inre01\Query Expansion pada Biografi\preprocessing.py", line 80, in token
    for word in CountVectorizer().build_tokenizer()(sentence):
  File "C:\Users\Pittri\Anaconda3\lib\site-packages\sklearn\feature_extraction\text.py", line 266, in <lambda>
    return lambda doc: token_pattern.findall(doc)
TypeError: expected string or bytes-like object
Exception on /analysis [GET]
Traceback (most recent call last):
  File "C:\Users\Pittri\Anaconda3\lib\site-packages\flask\app.py", line 2292, in wsgi_app
    response = self.full_dispatch_request()
  File "C:\Users\Pittri\Anaconda3\lib\site-packages\flask\app.py", line 1815, in full_dispatch_request
    rv = self.handle_user_exception(e)
  File "C:\Users\Pittri\Anaconda3\lib\site-packages\flask\app.py", line 1718, in handle_user_exception
    reraise(exc_type, exc_value, tb)
  File "C:\Users\Pittri\Anaconda3\lib\site-packages\flask\_compat.py", line 35, in reraise
    raise value
  File "C:\Users\Pittri\Anaconda3\lib\site-packages\flask\app.py", line 1813, in full_dispatch_request
    rv = self.dispatch_request()
  File "C:\Users\Pittri\Anaconda3\lib\site-packages\flask\app.py", line 1799, in dispatch_request
    return self.view_functions[rule.endpoint](**req.view_args)
  File "process.py", line 166, in analysis
    query = preprocessing.token(query)
  File "E:\inre01\Query Expansion pada Biografi\preprocessing.py", line 80, in token
    for word in CountVectorizer().build_tokenizer()(sentence):
  File "C:\Users\Pittri\Anaconda3\lib\site-packages\sklearn\feature_extraction\text.py", line 266, in <lambda>
    return lambda doc: token_pattern.findall(doc)
TypeError: expected string or bytes-like object
Exception on /analysis [GET]
Traceback (most recent call last):
  File "C:\Users\Pittri\Anaconda3\lib\site-packages\flask\app.py", line 2292, in wsgi_app
    response = self.full_dispatch_request()
  File "C:\Users\Pittri\Anaconda3\lib\site-packages\flask\app.py", line 1815, in full_dispatch_request
    rv = self.handle_user_exception(e)
  File "C:\Users\Pittri\Anaconda3\lib\site-packages\flask\app.py", line 1718, in handle_user_exception
    reraise(exc_type, exc_value, tb)
  File "C:\Users\Pittri\Anaconda3\lib\site-packages\flask\_compat.py", line 35, in reraise
    raise value
  File "C:\Users\Pittri\Anaconda3\lib\site-packages\flask\app.py", line 1813, in full_dispatch_request
    rv = self.dispatch_request()
  File "C:\Users\Pittri\Anaconda3\lib\site-packages\flask\app.py", line 1799, in dispatch_request
    return self.view_functions[rule.endpoint](**req.view_args)
  File "process.py", line 166, in analysis
    query = preprocessing.tokenization(query)
AttributeError: module 'preprocessing' has no attribute 'tokenization'
Exception on /analysis [GET]
Traceback (most recent call last):
  File "C:\Users\Pittri\Anaconda3\lib\site-packages\flask\app.py", line 2292, in wsgi_app
    response = self.full_dispatch_request()
  File "C:\Users\Pittri\Anaconda3\lib\site-packages\flask\app.py", line 1815, in full_dispatch_request
    rv = self.handle_user_exception(e)
  File "C:\Users\Pittri\Anaconda3\lib\site-packages\flask\app.py", line 1718, in handle_user_exception
    reraise(exc_type, exc_value, tb)
  File "C:\Users\Pittri\Anaconda3\lib\site-packages\flask\_compat.py", line 35, in reraise
    raise value
  File "C:\Users\Pittri\Anaconda3\lib\site-packages\flask\app.py", line 1813, in full_dispatch_request
    rv = self.dispatch_request()
  File "C:\Users\Pittri\Anaconda3\lib\site-packages\flask\app.py", line 1799, in dispatch_request
    return self.view_functions[rule.endpoint](**req.view_args)
  File "process.py", line 166, in analysis
    query = preprocessing.tokenization(query)
  File "E:\inre01\Query Expansion pada Biografi\preprocessing.py", line 82, in tokenization
    line = ''.join([i for i in line if not i.isdigit()])
UnboundLocalError: local variable 'line' referenced before assignment
Exception on /analysis [GET]
Traceback (most recent call last):
  File "C:\Users\Pittri\Anaconda3\lib\site-packages\flask\app.py", line 2292, in wsgi_app
    response = self.full_dispatch_request()
  File "C:\Users\Pittri\Anaconda3\lib\site-packages\flask\app.py", line 1815, in full_dispatch_request
    rv = self.handle_user_exception(e)
  File "C:\Users\Pittri\Anaconda3\lib\site-packages\flask\app.py", line 1718, in handle_user_exception
    reraise(exc_type, exc_value, tb)
  File "C:\Users\Pittri\Anaconda3\lib\site-packages\flask\_compat.py", line 35, in reraise
    raise value
  File "C:\Users\Pittri\Anaconda3\lib\site-packages\flask\app.py", line 1813, in full_dispatch_request
    rv = self.dispatch_request()
  File "C:\Users\Pittri\Anaconda3\lib\site-packages\flask\app.py", line 1799, in dispatch_request
    return self.view_functions[rule.endpoint](**req.view_args)
  File "process.py", line 174, in analysis
    query = preprocessing.queryInIndex(query, index)
  File "E:\inre01\Query Expansion pada Biografi\preprocessing.py", line 179, in queryInIndex
    if word in index:
TypeError: unhashable type: 'list'
Exception on /analysis [GET]
Traceback (most recent call last):
  File "C:\Users\Pittri\Anaconda3\lib\site-packages\flask\app.py", line 2292, in wsgi_app
    response = self.full_dispatch_request()
  File "C:\Users\Pittri\Anaconda3\lib\site-packages\flask\app.py", line 1815, in full_dispatch_request
    rv = self.handle_user_exception(e)
  File "C:\Users\Pittri\Anaconda3\lib\site-packages\flask\app.py", line 1718, in handle_user_exception
    reraise(exc_type, exc_value, tb)
  File "C:\Users\Pittri\Anaconda3\lib\site-packages\flask\_compat.py", line 35, in reraise
    raise value
  File "C:\Users\Pittri\Anaconda3\lib\site-packages\flask\app.py", line 1813, in full_dispatch_request
    rv = self.dispatch_request()
  File "C:\Users\Pittri\Anaconda3\lib\site-packages\flask\app.py", line 1799, in dispatch_request
    return self.view_functions[rule.endpoint](**req.view_args)
  File "process.py", line 186, in analysis
    docFrequency    = df(query, index)
NameError: name 'df' is not defined
Exception on /analysis [GET]
Traceback (most recent call last):
  File "C:\Users\Pittri\Anaconda3\lib\site-packages\flask\app.py", line 2292, in wsgi_app
    response = self.full_dispatch_request()
  File "C:\Users\Pittri\Anaconda3\lib\site-packages\flask\app.py", line 1815, in full_dispatch_request
    rv = self.handle_user_exception(e)
  File "C:\Users\Pittri\Anaconda3\lib\site-packages\flask\app.py", line 1718, in handle_user_exception
    reraise(exc_type, exc_value, tb)
  File "C:\Users\Pittri\Anaconda3\lib\site-packages\flask\_compat.py", line 35, in reraise
    raise value
  File "C:\Users\Pittri\Anaconda3\lib\site-packages\flask\app.py", line 1813, in full_dispatch_request
    rv = self.dispatch_request()
  File "C:\Users\Pittri\Anaconda3\lib\site-packages\flask\app.py", line 1799, in dispatch_request
    return self.view_functions[rule.endpoint](**req.view_args)
  File "process.py", line 193, in analysis
    print('Query: ', raw_query,'\n\n')
NameError: name 'raw_query' is not defined
Exception on /analysis [GET]
Traceback (most recent call last):
  File "C:\Users\Pittri\Anaconda3\lib\site-packages\flask\app.py", line 2292, in wsgi_app
    response = self.full_dispatch_request()
  File "C:\Users\Pittri\Anaconda3\lib\site-packages\flask\app.py", line 1815, in full_dispatch_request
    rv = self.handle_user_exception(e)
  File "C:\Users\Pittri\Anaconda3\lib\site-packages\flask\app.py", line 1718, in handle_user_exception
    reraise(exc_type, exc_value, tb)
  File "C:\Users\Pittri\Anaconda3\lib\site-packages\flask\_compat.py", line 35, in reraise
    raise value
  File "C:\Users\Pittri\Anaconda3\lib\site-packages\flask\app.py", line 1813, in full_dispatch_request
    rv = self.dispatch_request()
  File "C:\Users\Pittri\Anaconda3\lib\site-packages\flask\app.py", line 1799, in dispatch_request
    return self.view_functions[rule.endpoint](**req.view_args)
  File "process.py", line 213, in analysis
    return render_template('submit.html', a=documentNumber)
  File "C:\Users\Pittri\Anaconda3\lib\site-packages\flask\templating.py", line 135, in render_template
    context, ctx.app)
  File "C:\Users\Pittri\Anaconda3\lib\site-packages\flask\templating.py", line 117, in _render
    rv = template.render(context)
  File "C:\Users\Pittri\Anaconda3\lib\site-packages\jinja2\asyncsupport.py", line 76, in render
    return original_render(self, *args, **kwargs)
  File "C:\Users\Pittri\Anaconda3\lib\site-packages\jinja2\environment.py", line 1008, in render
    return self.environment.handle_exception(exc_info, True)
  File "C:\Users\Pittri\Anaconda3\lib\site-packages\jinja2\environment.py", line 780, in handle_exception
    reraise(exc_type, exc_value, tb)
  File "C:\Users\Pittri\Anaconda3\lib\site-packages\jinja2\_compat.py", line 37, in reraise
    raise value.with_traceback(tb)
  File "E:\inre01\Query Expansion pada Biografi\templates\submit.html", line 2, in top-level template code
    {% extends "base.html" %}
  File "E:\inre01\Query Expansion pada Biografi\templates\base.html", line 31, in top-level template code
    {% block content %}
  File "E:\inre01\Query Expansion pada Biografi\templates\submit.html", line 59, in block "content"
    {{ form.hidden_tag() }}
  File "C:\Users\Pittri\Anaconda3\lib\site-packages\jinja2\environment.py", line 430, in getattr
    return getattr(obj, attribute)
jinja2.exceptions.UndefinedError: 'form' is undefined
Exception on /analysis [GET]
Traceback (most recent call last):
  File "C:\Users\Pittri\Anaconda3\lib\site-packages\flask\app.py", line 2292, in wsgi_app
    response = self.full_dispatch_request()
  File "C:\Users\Pittri\Anaconda3\lib\site-packages\flask\app.py", line 1815, in full_dispatch_request
    rv = self.handle_user_exception(e)
  File "C:\Users\Pittri\Anaconda3\lib\site-packages\flask\app.py", line 1718, in handle_user_exception
    reraise(exc_type, exc_value, tb)
  File "C:\Users\Pittri\Anaconda3\lib\site-packages\flask\_compat.py", line 35, in reraise
    raise value
  File "C:\Users\Pittri\Anaconda3\lib\site-packages\flask\app.py", line 1813, in full_dispatch_request
    rv = self.dispatch_request()
  File "C:\Users\Pittri\Anaconda3\lib\site-packages\flask\app.py", line 1799, in dispatch_request
    return self.view_functions[rule.endpoint](**req.view_args)
  File "process.py", line 213, in analysis
    return render_template('submit.html', a=documentNumber)
  File "C:\Users\Pittri\Anaconda3\lib\site-packages\flask\templating.py", line 135, in render_template
    context, ctx.app)
  File "C:\Users\Pittri\Anaconda3\lib\site-packages\flask\templating.py", line 117, in _render
    rv = template.render(context)
  File "C:\Users\Pittri\Anaconda3\lib\site-packages\jinja2\asyncsupport.py", line 76, in render
    return original_render(self, *args, **kwargs)
  File "C:\Users\Pittri\Anaconda3\lib\site-packages\jinja2\environment.py", line 1008, in render
    return self.environment.handle_exception(exc_info, True)
  File "C:\Users\Pittri\Anaconda3\lib\site-packages\jinja2\environment.py", line 780, in handle_exception
    reraise(exc_type, exc_value, tb)
  File "C:\Users\Pittri\Anaconda3\lib\site-packages\jinja2\_compat.py", line 37, in reraise
    raise value.with_traceback(tb)
  File "E:\inre01\Query Expansion pada Biografi\templates\submit.html", line 2, in top-level template code
    {% extends "base.html" %}
  File "E:\inre01\Query Expansion pada Biografi\templates\base.html", line 31, in top-level template code
    {% block content %}
  File "E:\inre01\Query Expansion pada Biografi\templates\submit.html", line 59, in block "content"
    {{ form.hidden_tag() }}
  File "C:\Users\Pittri\Anaconda3\lib\site-packages\jinja2\environment.py", line 430, in getattr
    return getattr(obj, attribute)
jinja2.exceptions.UndefinedError: 'form' is undefined
Exception on /analysis [GET]
Traceback (most recent call last):
  File "C:\Users\Pittri\Anaconda3\lib\site-packages\flask\app.py", line 2292, in wsgi_app
    response = self.full_dispatch_request()
  File "C:\Users\Pittri\Anaconda3\lib\site-packages\flask\app.py", line 1815, in full_dispatch_request
    rv = self.handle_user_exception(e)
  File "C:\Users\Pittri\Anaconda3\lib\site-packages\flask\app.py", line 1718, in handle_user_exception
    reraise(exc_type, exc_value, tb)
  File "C:\Users\Pittri\Anaconda3\lib\site-packages\flask\_compat.py", line 35, in reraise
    raise value
  File "C:\Users\Pittri\Anaconda3\lib\site-packages\flask\app.py", line 1813, in full_dispatch_request
    rv = self.dispatch_request()
  File "C:\Users\Pittri\Anaconda3\lib\site-packages\flask\app.py", line 1799, in dispatch_request
    return self.view_functions[rule.endpoint](**req.view_args)
  File "process.py", line 213, in analysis
    return render_template('submit.html', a=documentNumber)
  File "C:\Users\Pittri\Anaconda3\lib\site-packages\flask\templating.py", line 135, in render_template
    context, ctx.app)
  File "C:\Users\Pittri\Anaconda3\lib\site-packages\flask\templating.py", line 117, in _render
    rv = template.render(context)
  File "C:\Users\Pittri\Anaconda3\lib\site-packages\jinja2\asyncsupport.py", line 76, in render
    return original_render(self, *args, **kwargs)
  File "C:\Users\Pittri\Anaconda3\lib\site-packages\jinja2\environment.py", line 1008, in render
    return self.environment.handle_exception(exc_info, True)
  File "C:\Users\Pittri\Anaconda3\lib\site-packages\jinja2\environment.py", line 780, in handle_exception
    reraise(exc_type, exc_value, tb)
  File "C:\Users\Pittri\Anaconda3\lib\site-packages\jinja2\_compat.py", line 37, in reraise
    raise value.with_traceback(tb)
  File "E:\inre01\Query Expansion pada Biografi\templates\submit.html", line 2, in top-level template code
    {% extends "base.html" %}
  File "E:\inre01\Query Expansion pada Biografi\templates\base.html", line 31, in top-level template code
    {% block content %}
  File "E:\inre01\Query Expansion pada Biografi\templates\submit.html", line 59, in block "content"
    {{ form.hidden_tag() }}
  File "C:\Users\Pittri\Anaconda3\lib\site-packages\jinja2\environment.py", line 430, in getattr
    return getattr(obj, attribute)
jinja2.exceptions.UndefinedError: 'form' is undefined
Exception on /analysis [GET]
Traceback (most recent call last):
  File "C:\Users\Pittri\Anaconda3\lib\site-packages\flask\app.py", line 2292, in wsgi_app
    response = self.full_dispatch_request()
  File "C:\Users\Pittri\Anaconda3\lib\site-packages\flask\app.py", line 1815, in full_dispatch_request
    rv = self.handle_user_exception(e)
  File "C:\Users\Pittri\Anaconda3\lib\site-packages\flask\app.py", line 1718, in handle_user_exception
    reraise(exc_type, exc_value, tb)
  File "C:\Users\Pittri\Anaconda3\lib\site-packages\flask\_compat.py", line 35, in reraise
    raise value
  File "C:\Users\Pittri\Anaconda3\lib\site-packages\flask\app.py", line 1813, in full_dispatch_request
    rv = self.dispatch_request()
  File "C:\Users\Pittri\Anaconda3\lib\site-packages\flask\app.py", line 1799, in dispatch_request
    return self.view_functions[rule.endpoint](**req.view_args)
  File "process.py", line 192, in analysis
    return render_template('submit.html', a=documentNumber)
  File "C:\Users\Pittri\Anaconda3\lib\site-packages\flask\templating.py", line 135, in render_template
    context, ctx.app)
  File "C:\Users\Pittri\Anaconda3\lib\site-packages\flask\templating.py", line 117, in _render
    rv = template.render(context)
  File "C:\Users\Pittri\Anaconda3\lib\site-packages\jinja2\asyncsupport.py", line 76, in render
    return original_render(self, *args, **kwargs)
  File "C:\Users\Pittri\Anaconda3\lib\site-packages\jinja2\environment.py", line 1008, in render
    return self.environment.handle_exception(exc_info, True)
  File "C:\Users\Pittri\Anaconda3\lib\site-packages\jinja2\environment.py", line 780, in handle_exception
    reraise(exc_type, exc_value, tb)
  File "C:\Users\Pittri\Anaconda3\lib\site-packages\jinja2\_compat.py", line 37, in reraise
    raise value.with_traceback(tb)
  File "E:\inre01\Query Expansion pada Biografi\templates\submit.html", line 2, in top-level template code
    {% extends "base.html" %}
  File "E:\inre01\Query Expansion pada Biografi\templates\base.html", line 31, in top-level template code
    {% block content %}
  File "E:\inre01\Query Expansion pada Biografi\templates\submit.html", line 59, in block "content"
    {{ form.hidden_tag() }}
  File "C:\Users\Pittri\Anaconda3\lib\site-packages\jinja2\environment.py", line 430, in getattr
    return getattr(obj, attribute)
jinja2.exceptions.UndefinedError: 'form' is undefined
Exception on /analysis [GET]
Traceback (most recent call last):
  File "C:\Users\Pittri\Anaconda3\lib\site-packages\flask\app.py", line 2292, in wsgi_app
    response = self.full_dispatch_request()
  File "C:\Users\Pittri\Anaconda3\lib\site-packages\flask\app.py", line 1815, in full_dispatch_request
    rv = self.handle_user_exception(e)
  File "C:\Users\Pittri\Anaconda3\lib\site-packages\flask\app.py", line 1718, in handle_user_exception
    reraise(exc_type, exc_value, tb)
  File "C:\Users\Pittri\Anaconda3\lib\site-packages\flask\_compat.py", line 35, in reraise
    raise value
  File "C:\Users\Pittri\Anaconda3\lib\site-packages\flask\app.py", line 1813, in full_dispatch_request
    rv = self.dispatch_request()
  File "C:\Users\Pittri\Anaconda3\lib\site-packages\flask\app.py", line 1799, in dispatch_request
    return self.view_functions[rule.endpoint](**req.view_args)
  File "process.py", line 213, in analysis
    return render_template('load.html', a=documentNumber, qs=query_search, fl=filename)
  File "C:\Users\Pittri\Anaconda3\lib\site-packages\flask\templating.py", line 134, in render_template
    return _render(ctx.app.jinja_env.get_or_select_template(template_name_or_list),
  File "C:\Users\Pittri\Anaconda3\lib\site-packages\jinja2\environment.py", line 869, in get_or_select_template
    return self.get_template(template_name_or_list, parent, globals)
  File "C:\Users\Pittri\Anaconda3\lib\site-packages\jinja2\environment.py", line 830, in get_template
    return self._load_template(name, self.make_globals(globals))
  File "C:\Users\Pittri\Anaconda3\lib\site-packages\jinja2\environment.py", line 804, in _load_template
    template = self.loader.load(self, name, globals)
  File "C:\Users\Pittri\Anaconda3\lib\site-packages\jinja2\loaders.py", line 125, in load
    code = environment.compile(source, name, filename)
  File "C:\Users\Pittri\Anaconda3\lib\site-packages\jinja2\environment.py", line 591, in compile
    self.handle_exception(exc_info, source_hint=source_hint)
  File "C:\Users\Pittri\Anaconda3\lib\site-packages\jinja2\environment.py", line 780, in handle_exception
    reraise(exc_type, exc_value, tb)
  File "C:\Users\Pittri\Anaconda3\lib\site-packages\jinja2\_compat.py", line 37, in reraise
    raise value.with_traceback(tb)
  File "E:\inre01\Query Expansion pada Biografi\templates\load.html", line 101, in template
    {% endblock %}
  File "C:\Users\Pittri\Anaconda3\lib\site-packages\jinja2\environment.py", line 497, in _parse
    return Parser(self, source, name, encode_filename(filename)).parse()
  File "C:\Users\Pittri\Anaconda3\lib\site-packages\jinja2\parser.py", line 901, in parse
    result = nodes.Template(self.subparse(), lineno=1)
  File "C:\Users\Pittri\Anaconda3\lib\site-packages\jinja2\parser.py", line 883, in subparse
    rv = self.parse_statement()
  File "C:\Users\Pittri\Anaconda3\lib\site-packages\jinja2\parser.py", line 130, in parse_statement
    return getattr(self, 'parse_' + self.stream.current.value)()
  File "C:\Users\Pittri\Anaconda3\lib\site-packages\jinja2\parser.py", line 268, in parse_block
    node.body = self.parse_statements(('name:endblock',), drop_needle=True)
  File "C:\Users\Pittri\Anaconda3\lib\site-packages\jinja2\parser.py", line 165, in parse_statements
    result = self.subparse(end_tokens)
  File "C:\Users\Pittri\Anaconda3\lib\site-packages\jinja2\parser.py", line 883, in subparse
    rv = self.parse_statement()
  File "C:\Users\Pittri\Anaconda3\lib\site-packages\jinja2\parser.py", line 130, in parse_statement
    return getattr(self, 'parse_' + self.stream.current.value)()
  File "C:\Users\Pittri\Anaconda3\lib\site-packages\jinja2\parser.py", line 199, in parse_for
    body = self.parse_statements(('name:endfor', 'name:else'))
  File "C:\Users\Pittri\Anaconda3\lib\site-packages\jinja2\parser.py", line 165, in parse_statements
    result = self.subparse(end_tokens)
  File "C:\Users\Pittri\Anaconda3\lib\site-packages\jinja2\parser.py", line 883, in subparse
    rv = self.parse_statement()
  File "C:\Users\Pittri\Anaconda3\lib\site-packages\jinja2\parser.py", line 144, in parse_statement
    self.fail_unknown_tag(token.value, token.lineno)
  File "C:\Users\Pittri\Anaconda3\lib\site-packages\jinja2\parser.py", line 97, in fail_unknown_tag
    return self._fail_ut_eof(name, self._end_token_stack, lineno)
  File "C:\Users\Pittri\Anaconda3\lib\site-packages\jinja2\parser.py", line 90, in _fail_ut_eof
    self.fail(' '.join(message), lineno)
  File "C:\Users\Pittri\Anaconda3\lib\site-packages\jinja2\parser.py", line 59, in fail
    raise exc(msg, lineno, self.name, self.filename)
jinja2.exceptions.TemplateSyntaxError: Encountered unknown tag 'endblock'. You probably made a nesting mistake. Jinja is expecting this tag, but currently looking for 'endfor' or 'else'. The innermost block that needs to be closed is 'for'.
Exception on /analysis [GET]
Traceback (most recent call last):
  File "C:\Users\Pittri\Anaconda3\lib\site-packages\flask\app.py", line 2292, in wsgi_app
    response = self.full_dispatch_request()
  File "C:\Users\Pittri\Anaconda3\lib\site-packages\flask\app.py", line 1815, in full_dispatch_request
    rv = self.handle_user_exception(e)
  File "C:\Users\Pittri\Anaconda3\lib\site-packages\flask\app.py", line 1718, in handle_user_exception
    reraise(exc_type, exc_value, tb)
  File "C:\Users\Pittri\Anaconda3\lib\site-packages\flask\_compat.py", line 35, in reraise
    raise value
  File "C:\Users\Pittri\Anaconda3\lib\site-packages\flask\app.py", line 1813, in full_dispatch_request
    rv = self.dispatch_request()
  File "C:\Users\Pittri\Anaconda3\lib\site-packages\flask\app.py", line 1799, in dispatch_request
    return self.view_functions[rule.endpoint](**req.view_args)
  File "process.py", line 217, in analysis
    return render_template('load.html', a=documentNumber, qs=query_search, fl=filename, ex=extracted)
  File "C:\Users\Pittri\Anaconda3\lib\site-packages\flask\templating.py", line 135, in render_template
    context, ctx.app)
  File "C:\Users\Pittri\Anaconda3\lib\site-packages\flask\templating.py", line 117, in _render
    rv = template.render(context)
  File "C:\Users\Pittri\Anaconda3\lib\site-packages\jinja2\asyncsupport.py", line 76, in render
    return original_render(self, *args, **kwargs)
  File "C:\Users\Pittri\Anaconda3\lib\site-packages\jinja2\environment.py", line 1008, in render
    return self.environment.handle_exception(exc_info, True)
  File "C:\Users\Pittri\Anaconda3\lib\site-packages\jinja2\environment.py", line 780, in handle_exception
    reraise(exc_type, exc_value, tb)
  File "C:\Users\Pittri\Anaconda3\lib\site-packages\jinja2\_compat.py", line 37, in reraise
    raise value.with_traceback(tb)
  File "E:\inre01\Query Expansion pada Biografi\templates\load.html", line 2, in top-level template code
    {% extends "base.html" %}
  File "E:\inre01\Query Expansion pada Biografi\templates\base.html", line 31, in top-level template code
    {% block content %}
  File "E:\inre01\Query Expansion pada Biografi\templates\load.html", line 66, in block "content"
    <tr><td> <p> Judul : {{extracted[i]}} </p></td></tr>
  File "C:\Users\Pittri\Anaconda3\lib\site-packages\jinja2\environment.py", line 411, in getitem
    return obj[argument]
jinja2.exceptions.UndefinedError: 'extracted' is undefined
Exception on /analysis [GET]
Traceback (most recent call last):
  File "C:\Users\Pittri\Anaconda3\lib\site-packages\flask\app.py", line 2292, in wsgi_app
    response = self.full_dispatch_request()
  File "C:\Users\Pittri\Anaconda3\lib\site-packages\flask\app.py", line 1815, in full_dispatch_request
    rv = self.handle_user_exception(e)
  File "C:\Users\Pittri\Anaconda3\lib\site-packages\flask\app.py", line 1718, in handle_user_exception
    reraise(exc_type, exc_value, tb)
  File "C:\Users\Pittri\Anaconda3\lib\site-packages\flask\_compat.py", line 35, in reraise
    raise value
  File "C:\Users\Pittri\Anaconda3\lib\site-packages\flask\app.py", line 1813, in full_dispatch_request
    rv = self.dispatch_request()
  File "C:\Users\Pittri\Anaconda3\lib\site-packages\flask\app.py", line 1799, in dispatch_request
    return self.view_functions[rule.endpoint](**req.view_args)
  File "process.py", line 217, in analysis
    return render_template('load.html', a=documentNumber, qs=query_search, fl=filename, ex=extracted)
  File "C:\Users\Pittri\Anaconda3\lib\site-packages\flask\templating.py", line 135, in render_template
    context, ctx.app)
  File "C:\Users\Pittri\Anaconda3\lib\site-packages\flask\templating.py", line 117, in _render
    rv = template.render(context)
  File "C:\Users\Pittri\Anaconda3\lib\site-packages\jinja2\asyncsupport.py", line 76, in render
    return original_render(self, *args, **kwargs)
  File "C:\Users\Pittri\Anaconda3\lib\site-packages\jinja2\environment.py", line 1008, in render
    return self.environment.handle_exception(exc_info, True)
  File "C:\Users\Pittri\Anaconda3\lib\site-packages\jinja2\environment.py", line 780, in handle_exception
    reraise(exc_type, exc_value, tb)
  File "C:\Users\Pittri\Anaconda3\lib\site-packages\jinja2\_compat.py", line 37, in reraise
    raise value.with_traceback(tb)
  File "E:\inre01\Query Expansion pada Biografi\templates\load.html", line 2, in top-level template code
    {% extends "base.html" %}
  File "E:\inre01\Query Expansion pada Biografi\templates\base.html", line 31, in top-level template code
    {% block content %}
  File "E:\inre01\Query Expansion pada Biografi\templates\load.html", line 66, in block "content"
    <!-- <tr><td> <p> Judul : {{extracted[i]}} </p></td></tr> -->
  File "C:\Users\Pittri\Anaconda3\lib\site-packages\jinja2\environment.py", line 411, in getitem
    return obj[argument]
jinja2.exceptions.UndefinedError: 'extracted' is undefined
Exception on /analysis [GET]
Traceback (most recent call last):
  File "C:\Users\Pittri\Anaconda3\lib\site-packages\flask\app.py", line 2292, in wsgi_app
    response = self.full_dispatch_request()
  File "C:\Users\Pittri\Anaconda3\lib\site-packages\flask\app.py", line 1815, in full_dispatch_request
    rv = self.handle_user_exception(e)
  File "C:\Users\Pittri\Anaconda3\lib\site-packages\flask\app.py", line 1718, in handle_user_exception
    reraise(exc_type, exc_value, tb)
  File "C:\Users\Pittri\Anaconda3\lib\site-packages\flask\_compat.py", line 35, in reraise
    raise value
  File "C:\Users\Pittri\Anaconda3\lib\site-packages\flask\app.py", line 1813, in full_dispatch_request
    rv = self.dispatch_request()
  File "C:\Users\Pittri\Anaconda3\lib\site-packages\flask\app.py", line 1799, in dispatch_request
    return self.view_functions[rule.endpoint](**req.view_args)
  File "process.py", line 217, in analysis
    return render_template('load.html', a=documentNumber, qs=query_search, fl=filename, ex=extracted)
  File "C:\Users\Pittri\Anaconda3\lib\site-packages\flask\templating.py", line 135, in render_template
    context, ctx.app)
  File "C:\Users\Pittri\Anaconda3\lib\site-packages\flask\templating.py", line 117, in _render
    rv = template.render(context)
  File "C:\Users\Pittri\Anaconda3\lib\site-packages\jinja2\asyncsupport.py", line 76, in render
    return original_render(self, *args, **kwargs)
  File "C:\Users\Pittri\Anaconda3\lib\site-packages\jinja2\environment.py", line 1008, in render
    return self.environment.handle_exception(exc_info, True)
  File "C:\Users\Pittri\Anaconda3\lib\site-packages\jinja2\environment.py", line 780, in handle_exception
    reraise(exc_type, exc_value, tb)
  File "C:\Users\Pittri\Anaconda3\lib\site-packages\jinja2\_compat.py", line 37, in reraise
    raise value.with_traceback(tb)
  File "E:\inre01\Query Expansion pada Biografi\templates\load.html", line 2, in top-level template code
    {% extends "base.html" %}
  File "E:\inre01\Query Expansion pada Biografi\templates\base.html", line 31, in top-level template code
    {% block content %}
  File "E:\inre01\Query Expansion pada Biografi\templates\load.html", line 66, in block "content"
    <!-- <tr><td> <p> Judul : {{extracted[i]}} </p></td></tr> -->
  File "C:\Users\Pittri\Anaconda3\lib\site-packages\jinja2\environment.py", line 411, in getitem
    return obj[argument]
jinja2.exceptions.UndefinedError: 'extracted' is undefined
Exception on /analysis [GET]
Traceback (most recent call last):
  File "C:\Users\Pittri\Anaconda3\lib\site-packages\flask\app.py", line 2292, in wsgi_app
    response = self.full_dispatch_request()
  File "C:\Users\Pittri\Anaconda3\lib\site-packages\flask\app.py", line 1815, in full_dispatch_request
    rv = self.handle_user_exception(e)
  File "C:\Users\Pittri\Anaconda3\lib\site-packages\flask\app.py", line 1718, in handle_user_exception
    reraise(exc_type, exc_value, tb)
  File "C:\Users\Pittri\Anaconda3\lib\site-packages\flask\_compat.py", line 35, in reraise
    raise value
  File "C:\Users\Pittri\Anaconda3\lib\site-packages\flask\app.py", line 1813, in full_dispatch_request
    rv = self.dispatch_request()
  File "C:\Users\Pittri\Anaconda3\lib\site-packages\flask\app.py", line 1799, in dispatch_request
    return self.view_functions[rule.endpoint](**req.view_args)
  File "process.py", line 217, in analysis
    return render_template('load.html', a=documentNumber, qs=query_search, fl=filename)
  File "C:\Users\Pittri\Anaconda3\lib\site-packages\flask\templating.py", line 135, in render_template
    context, ctx.app)
  File "C:\Users\Pittri\Anaconda3\lib\site-packages\flask\templating.py", line 117, in _render
    rv = template.render(context)
  File "C:\Users\Pittri\Anaconda3\lib\site-packages\jinja2\asyncsupport.py", line 76, in render
    return original_render(self, *args, **kwargs)
  File "C:\Users\Pittri\Anaconda3\lib\site-packages\jinja2\environment.py", line 1008, in render
    return self.environment.handle_exception(exc_info, True)
  File "C:\Users\Pittri\Anaconda3\lib\site-packages\jinja2\environment.py", line 780, in handle_exception
    reraise(exc_type, exc_value, tb)
  File "C:\Users\Pittri\Anaconda3\lib\site-packages\jinja2\_compat.py", line 37, in reraise
    raise value.with_traceback(tb)
  File "E:\inre01\Query Expansion pada Biografi\templates\load.html", line 2, in top-level template code
    {% extends "base.html" %}
  File "E:\inre01\Query Expansion pada Biografi\templates\base.html", line 31, in top-level template code
    {% block content %}
  File "E:\inre01\Query Expansion pada Biografi\templates\load.html", line 66, in block "content"
    <!-- <tr><td> <p> Judul : {{extracted[i]}} </p></td></tr> -->
  File "C:\Users\Pittri\Anaconda3\lib\site-packages\jinja2\environment.py", line 411, in getitem
    return obj[argument]
jinja2.exceptions.UndefinedError: 'extracted' is undefined
Exception on /analysis [GET]
Traceback (most recent call last):
  File "C:\Users\Pittri\Anaconda3\lib\site-packages\flask\app.py", line 2292, in wsgi_app
    response = self.full_dispatch_request()
  File "C:\Users\Pittri\Anaconda3\lib\site-packages\flask\app.py", line 1815, in full_dispatch_request
    rv = self.handle_user_exception(e)
  File "C:\Users\Pittri\Anaconda3\lib\site-packages\flask\app.py", line 1718, in handle_user_exception
    reraise(exc_type, exc_value, tb)
  File "C:\Users\Pittri\Anaconda3\lib\site-packages\flask\_compat.py", line 35, in reraise
    raise value
  File "C:\Users\Pittri\Anaconda3\lib\site-packages\flask\app.py", line 1813, in full_dispatch_request
    rv = self.dispatch_request()
  File "C:\Users\Pittri\Anaconda3\lib\site-packages\flask\app.py", line 1799, in dispatch_request
    return self.view_functions[rule.endpoint](**req.view_args)
  File "process.py", line 206, in analysis
    relevanceDocNumber.append(int(sc[i]))
IndexError: list index out of range
